Workbook

Sheet README
B4: Project: Poland Market Dashboard
B5: Purpose: Monitoring Polish equity indices, PLN exchange rates and gold prices.
B6: Data sources: GPW and NBP
B7: Frequency: Daily
B8: Tools: Excel, Power Query / NBP API
B9: Metrics: 1D, 5D, MTD, return since 06.03, 20D volatility, drawdown
B10: Disclaimer: Educational project, not investment advice.
B15: Static market snapshot as of 02.06.2026.

Sheet Raw_GPW
C3: wig20 | M3: mwig40 | W3: swig80
C5: Data | D5: Otwarcie | E5: Najwyzszy | F5: Najnizszy | G5: Zamkniecie | H5: Wolumen | M5: Data | N5: Otwarcie | O5: Najwyzszy | P5: Najnizszy | Q5: Zamkniecie | R5: Wolumen | W5: Data | X5: Otwarcie | Y5: Najwyzszy | Z5: Najnizszy | AA5: Zamkniecie | AB5: Wolumen
C6: 46087 | D6: 3349.06 | E6: 3349.06 | F6: 3244.45 | G6: 3262.33 | H6: 35225960 | M6: 46087 | N6: 8731.67 | O6: 8739.08 | P6: 8472.49 | Q6: 8516.38 | R6: 9318886 | W6: 46087 | X6: 31111.28 | Y6: 31111.28 | Z6: 30460.39 | AA6: 30658.34 | AB6: 3225309
C7: 46090 | D7: 3212.39 | E7: 3265.24 | F7: 3182.92 | G7: 3256.8 | H7: 31466995 | M7: 46090 | N7: 8391.68 | O7: 8495.42 | P7: 8328.1 | Q7: 8474.65 | R7: 11422123 | W7: 46090 | X7: 30138.4 | Y7: 30384.66 | Z7: 29995.45 | AA7: 30384.66 | AB7: 5443518
C8: 46091 | D8: 3324.61 | E8: 3348.02 | F8: 3310.49 | G8: 3327.28 | H8: 24304250 | M8: 46091 | N8: 8651.16 | O8: 8708.84 | P8: 8521.03 | Q8: 8578.78 | R8: 8120608 | W8: 46091 | X8: 30649.13 | Y8: 30900.75 | Z8: 30589.76 | AA8: 30686.76 | AB8: 4070966
C9: 46092 | D9: 3324.09 | E9: 3330.6 | F9: 3288.52 | G9: 3312.71 | H9: 27372506 | M9: 46092 | N9: 8619.7 | O9: 8619.7 | P9: 8448.78 | Q9: 8472.15 | R9: 10045249 | W9: 46092 | X9: 30802.05 | Y9: 30806.66 | Z9: 30567.63 | AA9: 30604.91 | AB9: 3430285
C10: 46093 | D10: 3327.68 | E10: 3329.98 | F10: 3252.34 | G10: 3291.27 | H10: 32406811 | M10: 46093 | N10: 8491.5 | O10: 8491.5 | P10: 8322.45 | Q10: 8357.95 | R10: 8360264 | W10: 46093 | X10: 30660.81 | Y10: 30685.51 | Z10: 30177.26 | AA10: 30349.83 | AB10: 3973260
C11: 46094 | D11: 3263.95 | E11: 3310.71 | F11: 3249.92 | G11: 3274.54 | H11: 28176970 | M11: 46094 | N11: 8339.35 | O11: 8421.92 | P11: 8267.12 | Q11: 8361.59 | R11: 10953765 | W11: 46094 | X11: 30257.71 | Y11: 30331.54 | Z11: 30021.68 | AA11: 30235.7 | AB11: 3346764
C12: 46097 | D12: 3281.31 | E12: 3305.54 | F12: 3259.04 | G12: 3292.46 | H12: 20979461 | M12: 46097 | N12: 8389.1 | O12: 8396.41 | P12: 8267.37 | Q12: 8361.63 | R12: 9323991 | W12: 46097 | X12: 30289.12 | Y12: 30304.56 | Z12: 30035.7 | AA12: 30233.82 | AB12: 4362680
C13: 46098 | D13: 3290.39 | E13: 3373.93 | F13: 3287.89 | G13: 3359.96 | H13: 34518048 | M13: 46098 | N13: 8396.15 | O13: 8623.55 | P13: 8353.59 | Q13: 8623.55 | R13: 11845878 | W13: 46098 | X13: 30273.54 | Y13: 30499.4 | Z13: 30180.16 | AA13: 30485.61 | AB13: 6876014
C14: 46099 | D14: 3379.99 | E14: 3408.97 | F14: 3338.2 | G14: 3338.2 | H14: 29911477 | M14: 46099 | N14: 8673.73 | O14: 8716.65 | P14: 8527.87 | Q14: 8537.47 | R14: 13579688 | W14: 46099 | X14: 30593.28 | Y14: 30695.03 | Z14: 30315.52 | AA14: 30315.52 | AB14: 4643251
C15: 46100 | D15: 3315.79 | E15: 3315.79 | F15: 3266.46 | G15: 3276.57 | H15: 36177727 | M15: 46100 | N15: 8525.93 | O15: 8525.93 | P15: 8380.77 | Q15: 8418.91 | R15: 13074387 | W15: 46100 | X15: 30260.21 | Y15: 30260.21 | Z15: 29767.97 | AA15: 29835.38 | AB15: 7829924
C16: 46101 | D16: 3297.49 | E16: 3309.63 | F16: 3230.89 | G16: 3248.12 | H16: 71769333 | M16: 46101 | N16: 8489.56 | O16: 8489.56 | P16: 8191.21 | Q16: 8247.07 | R16: 38299941 | W16: 46101 | X16: 29986.41 | Y16: 30043.04 | Z16: 29641.24 | AA16: 29641.24 | AB16: 6925018
C17: 46104 | D17: 3200.99 | E17: 3293.34 | F17: 3134.6 | G17: 3268.15 | H17: 36155589 | M17: 46104 | N17: 8120.29 | O17: 8343.89 | P17: 7992.65 | Q17: 8297.37 | R17: 20163484 | W17: 46104 | X17: 29195.36 | Y17: 29339.65 | Z17: 28552.32 | AA17: 29248.18 | AB17: 7913812
... C65: 46175 | D65: 3667.37 | E65: 3715.27 | F65: 3643.36 | G65: 3668.51 | H65: 33302186 | M65: 46175 | N65: 9492.44 | O65: 9611.1 | P65: 9492.44 | Q65: 9530.78 | R65: 18902408 | W65: 46175 | X65: 32380.95 | Y65: 32635.25 | Z65: 32220.99 | AA65: 32283.9 | AB65: 6654040

Sheet Raw_NBP
D3: USD/PLN | K3: EUR/PLN | R3: złoto
D5: no | E5: effectiveDate | F5: mid | K5: no | L5: effectiveDate | M5: mid | R5: data | S5: cena
D6: 045/A/NBP/2026 | E6: 2026-03-06 | F6: 3.6962 | K6: 045/A/NBP/2026 | L6: 2026-03-06 | M6: 4.2782 | R6: 2026-03-06 | S6: 609.99
D7: 046/A/NBP/2026 | E7: 2026-03-09 | F7: 3.7075 | K7: 046/A/NBP/2026 | L7: 2026-03-09 | M7: 4.2836 | R7: 2026-03-09 | S7: 604.25
D8: 047/A/NBP/2026 | E8: 2026-03-10 | F8: 3.6523 | K8: 047/A/NBP/2026 | L8: 2026-03-10 | M8: 4.2555 | R8: 2026-03-10 | S8: 608.44
D9: 048/A/NBP/2026 | E9: 2026-03-11 | F9: 3.687 | K9: 048/A/NBP/2026 | L9: 2026-03-11 | M9: 4.274 | R9: 2026-03-11 | S9: 608.47
D10: 049/A/NBP/2026 | E10: 2026-03-12 | F10: 3.6878 | K10: 049/A/NBP/2026 | L10: 2026-03-12 | M10: 4.2629 | R10: 2026-03-12 | S10: 614.84
D11: 050/A/NBP/2026 | E11: 2026-03-13 | F11: 3.7277 | K11: 050/A/NBP/2026 | L11: 2026-03-13 | M11: 4.2693 | R11: 2026-03-13 | S11: 615.05
D12: 051/A/NBP/2026 | E12: 2026-03-16 | F12: 3.7287 | K12: 051/A/NBP/2026 | L12: 2026-03-16 | M12: 4.2694 | R12: 2026-03-16 | S12: 609.89
D13: 052/A/NBP/2026 | E13: 2026-03-17 | F13: 3.7046 | K13: 052/A/NBP/2026 | L13: 2026-03-17 | M13: 4.2666 | R13: 2026-03-17 | S13: 596.33
D14: 053/A/NBP/2026 | E14: 2026-03-18 | F14: 3.693 | K14: 053/A/NBP/2026 | L14: 2026-03-18 | M14: 4.2613 | R14: 2026-03-18 | S14: 596.66
D15: 054/A/NBP/2026 | E15: 2026-03-19 | F15: 3.727 | K15: 054/A/NBP/2026 | L15: 2026-03-19 | M15: 4.2782 | R15: 2026-03-19 | S15: 592.62
D16: 055/A/NBP/2026 | E16: 2026-03-20 | F16: 3.7032 | K16: 055/A/NBP/2026 | L16: 2026-03-20 | M16: 4.2768 | R16: 2026-03-20 | S16: 562.93
D17: 056/A/NBP/2026 | E17: 2026-03-23 | F17: 3.7292 | K17: 056/A/NBP/2026 | L17: 2026-03-23 | M17: 4.2867 | R17: 2026-03-23 | S17: 555.59
... D66: 105/A/NBP/2026 | E66: 2026-06-02 | F66: 3.6358 | K66: 105/A/NBP/2026 | L66: 2026-06-02 | M66: 4.2334 | R66: 2026-06-02 | S66: 525.1

Sheet Clean_Data
G3: Date | H3: WIG20 | I3: mWIG40 | J3: sWIG80 | K3: USDPLN | L3: EURPLN | M3: GoldPLN | O3: WIG20_num
G4: =Raw_GPW!C6 -> 46087 | H4: =Raw_GPW!G6 -> 3262.33 | I4: =_xlfn.XLOOKUP(G4,Raw_GPW!M:M,Raw_GPW!Q:Q,"") -> 8516.38 | J4: =_xlfn.XLOOKUP(G4,Raw_GPW!W:W,Raw_GPW!AA:AA,"") -> 30658.34 | K4: =_xlfn.XLOOKUP(TEXT(G4,"rrrr-mm-dd"),Raw_NBP!E:E,Raw_NBP!F:F,"") -> 3.6962 | L4: =_xlfn.XLOOKUP(TEXT(G4,"rrrr-mm-dd"),Raw_NBP!L:L,Raw_NBP!M:M,"") -> 4.2782 | M4: =_xlfn.XLOOKUP(TEXT(G4,"rrrr-mm-dd"),Raw_NBP!R:R,Raw_NBP!S:S,"") -> 609.99 | O4: =_xlfn.NUMBERVALUE(H4,".",",") -> 3262.33
G5: =Raw_GPW!C7 -> 46090 | H5: =Raw_GPW!G7 -> 3256.8 | I5: =_xlfn.XLOOKUP(G5,Raw_GPW!M:M,Raw_GPW!Q:Q,"") -> 8474.65 | J5: =_xlfn.XLOOKUP(G5,Raw_GPW!W:W,Raw_GPW!AA:AA,"") -> 30384.66 | K5: =_xlfn.XLOOKUP(TEXT(G5,"rrrr-mm-dd"),Raw_NBP!E:E,Raw_NBP!F:F,"") -> 3.7075 | L5: =_xlfn.XLOOKUP(TEXT(G5,"rrrr-mm-dd"),Raw_NBP!L:L,Raw_NBP!M:M,"") -> 4.2836 | M5: =_xlfn.XLOOKUP(TEXT(G5,"rrrr-mm-dd"),Raw_NBP!R:R,Raw_NBP!S:S,"") -> 604.25 | O5: =_xlfn.NUMBERVALUE(H5,".",",") -> 3256.8
G6: =Raw_GPW!C8 -> 46091 | H6: =Raw_GPW!G8 -> 3327.28 | I6: =_xlfn.XLOOKUP(G6,Raw_GPW!M:M,Raw_GPW!Q:Q,"") -> 8578.78 | J6: =_xlfn.XLOOKUP(G6,Raw_GPW!W:W,Raw_GPW!AA:AA,"") -> 30686.76 | K6: =_xlfn.XLOOKUP(TEXT(G6,"rrrr-mm-dd"),Raw_NBP!E:E,Raw_NBP!F:F,"") -> 3.6523 | L6: =_xlfn.XLOOKUP(TEXT(G6,"rrrr-mm-dd"),Raw_NBP!L:L,Raw_NBP!M:M,"") -> 4.2555 | M6: =_xlfn.XLOOKUP(TEXT(G6,"rrrr-mm-dd"),Raw_NBP!R:R,Raw_NBP!S:S,"") -> 608.44 | O6: =_xlfn.NUMBERVALUE(H6,".",",") -> 3327.28
G7: =Raw_GPW!C9 -> 46092 | H7: =Raw_GPW!G9 -> 3312.71 | I7: =_xlfn.XLOOKUP(G7,Raw_GPW!M:M,Raw_GPW!Q:Q,"") -> 8472.15 | J7: =_xlfn.XLOOKUP(G7,Raw_GPW!W:W,Raw_GPW!AA:AA,"") -> 30604.91 | K7: =_xlfn.XLOOKUP(TEXT(G7,"rrrr-mm-dd"),Raw_NBP!E:E,Raw_NBP!F:F,"") -> 3.687 | L7: =_xlfn.XLOOKUP(TEXT(G7,"rrrr-mm-dd"),Raw_NBP!L:L,Raw_NBP!M:M,"") -> 4.274 | M7: =_xlfn.XLOOKUP(TEXT(G7,"rrrr-mm-dd"),Raw_NBP!R:R,Raw_NBP!S:S,"") -> 608.47 | O7: =_xlfn.NUMBERVALUE(H7,".",",") -> 3312.71
G8: =Raw_GPW!C10 -> 46093 | H8: =Raw_GPW!G10 -> 3291.27 | I8: =_xlfn.XLOOKUP(G8,Raw_GPW!M:M,Raw_GPW!Q:Q,"") -> 8357.95 | J8: =_xlfn.XLOOKUP(G8,Raw_GPW!W:W,Raw_GPW!AA:AA,"") -> 30349.83 | K8: =_xlfn.XLOOKUP(TEXT(G8,"rrrr-mm-dd"),Raw_NBP!E:E,Raw_NBP!F:F,"") -> 3.6878 | L8: =_xlfn.XLOOKUP(TEXT(G8,"rrrr-mm-dd"),Raw_NBP!L:L,Raw_NBP!M:M,"") -> 4.2629 | M8: =_xlfn.XLOOKUP(TEXT(G8,"rrrr-mm-dd"),Raw_NBP!R:R,Raw_NBP!S:S,"") -> 614.84 | O8: =_xlfn.NUMBERVALUE(H8,".",",") -> 3291.27
G9: =Raw_GPW!C11 -> 46094 | H9: =Raw_GPW!G11 -> 3274.54 | I9: =_xlfn.XLOOKUP(G9,Raw_GPW!M:M,Raw_GPW!Q:Q,"") -> 8361.59 | J9: =_xlfn.XLOOKUP(G9,Raw_GPW!W:W,Raw_GPW!AA:AA,"") -> 30235.7 | K9: =_xlfn.XLOOKUP(TEXT(G9,"rrrr-mm-dd"),Raw_NBP!E:E,Raw_NBP!F:F,"") -> 3.7277 | L9: =_xlfn.XLOOKUP(TEXT(G9,"rrrr-mm-dd"),Raw_NBP!L:L,Raw_NBP!M:M,"") -> 4.2693 | M9: =_xlfn.XLOOKUP(TEXT(G9,"rrrr-mm-dd"),Raw_NBP!R:R,Raw_NBP!S:S,"") -> 615.05 | O9: =_xlfn.NUMBERVALUE(H9,".",",") -> 3274.54
G10: =Raw_GPW!C12 -> 46097 | H10: =Raw_GPW!G12 -> 3292.46 | I10: =_xlfn.XLOOKUP(G10,Raw_GPW!M:M,Raw_GPW!Q:Q,"") -> 8361.63 | J10: =_xlfn.XLOOKUP(G10,Raw_GPW!W:W,Raw_GPW!AA:AA,"") -> 30233.82 | K10: =_xlfn.XLOOKUP(TEXT(G10,"rrrr-mm-dd"),Raw_NBP!E:E,Raw_NBP!F:F,"") -> 3.7287 | L10: =_xlfn.XLOOKUP(TEXT(G10,"rrrr-mm-dd"),Raw_NBP!L:L,Raw_NBP!M:M,"") -> 4.2694 | M10: =_xlfn.XLOOKUP(TEXT(G10,"rrrr-mm-dd"),Raw_NBP!R:R,Raw_NBP!S:S,"") -> 609.89 | O10: =_xlfn.NUMBERVALUE(H10,".",",") -> 3292.46
G11: =Raw_GPW!C13 -> 46098 | H11: =Raw_GPW!G13 -> 3359.96 | I11: =_xlfn.XLOOKUP(G11,Raw_GPW!M:M,Raw_GPW!Q:Q,"") -> 8623.55 | J11: =_xlfn.XLOOKUP(G11,Raw_GPW!W:W,Raw_GPW!AA:AA,"") -> 30485.61 | K11: =_xlfn.XLOOKUP(TEXT(G11,"rrrr-mm-dd"),Raw_NBP!E:E,Raw_NBP!F:F,"") -> 3.7046 | L11: =_xlfn.XLOOKUP(TEXT(G11,"rrrr-mm-dd"),Raw_NBP!L:L,Raw_NBP!M:M,"") -> 4.2666 | M11: =_xlfn.XLOOKUP(TEXT(G11,"rrrr-mm-dd"),Raw_NBP!R:R,Raw_NBP!S:S,"") -> 596.33 | O11: =_xlfn.NUMBERVALUE(H11,".",",") -> 3359.96
G12: =Raw_GPW!C14 -> 46099 | H12: =Raw_GPW!G14 -> 3338.2 | I12: =_xlfn.XLOOKUP(G12,Raw_GPW!M:M,Raw_GPW!Q:Q,"") -> 8537.47 | J12: =_xlfn.XLOOKUP(G12,Raw_GPW!W:W,Raw_GPW!AA:AA,"") -> 30315.52 | K12: =_xlfn.XLOOKUP(TEXT(G12,"rrrr-mm-dd"),Raw_NBP!E:E,Raw_NBP!F:F,"") -> 3.693 | L12: =_xlfn.XLOOKUP(TEXT(G12,"rrrr-mm-dd"),Raw_NBP!L:L,Raw_NBP!M:M,"") -> 4.2613 | M12: =_xlfn.XLOOKUP(TEXT(G12,"rrrr-mm-dd"),Raw_NBP!R:R,Raw_NBP!S:S,"") -> 596.66 | O12: =_xlfn.NUMBERVALUE(H12,".",",") -> 3338.2
G13: =Raw_GPW!C15 -> 46100 | H13: =Raw_GPW!G15 -> 3276.57 | I13: =_xlfn.XLOOKUP(G13,Raw_GPW!M:M,Raw_GPW!Q:Q,"") -> 8418.91 | J13: =_xlfn.XLOOKUP(G13,Raw_GPW!W:W,Raw_GPW!AA:AA,"") -> 29835.38 | K13: =_xlfn.XLOOKUP(TEXT(G13,"rrrr-mm-dd"),Raw_NBP!E:E,Raw_NBP!F:F,"") -> 3.727 | L13: =_xlfn.XLOOKUP(TEXT(G13,"rrrr-mm-dd"),Raw_NBP!L:L,Raw_NBP!M:M,"") -> 4.2782 | M13: =_xlfn.XLOOKUP(TEXT(G13,"rrrr-mm-dd"),Raw_NBP!R:R,Raw_NBP!S:S,"") -> 592.62 | O13: =_xlfn.NUMBERVALUE(H13,".",",") -> 3276.57
G14: =Raw_GPW!C16 -> 46101 | H14: =Raw_GPW!G16 -> 3248.12 | I14: =_xlfn.XLOOKUP(G14,Raw_GPW!M:M,Raw_GPW!Q:Q,"") -> 8247.07 | J14: =_xlfn.XLOOKUP(G14,Raw_GPW!W:W,Raw_GPW!AA:AA,"") -> 29641.24 | K14: =_xlfn.XLOOKUP(TEXT(G14,"rrrr-mm-dd"),Raw_NBP!E:E,Raw_NBP!F:F,"") -> 3.7032 | L14: =_xlfn.XLOOKUP(TEXT(G14,"rrrr-mm-dd"),Raw_NBP!L:L,Raw_NBP!M:M,"") -> 4.2768 | M14: =_xlfn.XLOOKUP(TEXT(G14,"rrrr-mm-dd"),Raw_NBP!R:R,Raw_NBP!S:S,"") -> 562.93 | O14: =_xlfn.NUMBERVALUE(H14,".",",") -> 3248.12
G15: =Raw_GPW!C17 -> 46104 | H15: =Raw_GPW!G17 -> 3268.15 | I15: =_xlfn.XLOOKUP(G15,Raw_GPW!M:M,Raw_GPW!Q:Q,"") -> 8297.37 | J15: =_xlfn.XLOOKUP(G15,Raw_GPW!W:W,Raw_GPW!AA:AA,"") -> 29248.18 | K15: =_xlfn.XLOOKUP(TEXT(G15,"rrrr-mm-dd"),Raw_NBP!E:E,Raw_NBP!F:F,"") -> 3.7292 | L15: =_xlfn.XLOOKUP(TEXT(G15,"rrrr-mm-dd"),Raw_NBP!L:L,Raw_NBP!M:M,"") -> 4.2867 | M15: =_xlfn.XLOOKUP(TEXT(G15,"rrrr-mm-dd"),Raw_NBP!R:R,Raw_NBP!S:S,"") -> 555.59 | O15: =_xlfn.NUMBERVALUE(H15,".",",") -> 3268.15
... G63: =Raw_GPW!C65 -> 46175 | H63: =Raw_GPW!G65 -> 3668.51 | I63: =_xlfn.XLOOKUP(G63,Raw_GPW!M:M,Raw_GPW!Q:Q,"") -> 9530.78 | J63: =_xlfn.XLOOKUP(G63,Raw_GPW!W:W,Raw_GPW!AA:AA,"") -> 32283.9 | K63: =_xlfn.XLOOKUP(TEXT(G63,"rrrr-mm-dd"),Raw_NBP!E:E,Raw_NBP!F:F,"") -> 3.6358 | L63: =_xlfn.XLOOKUP(TEXT(G63,"rrrr-mm-dd"),Raw_NBP!L:L,Raw_NBP!M:M,"") -> 4.2334 | M63: =_xlfn.XLOOKUP(TEXT(G63,"rrrr-mm-dd"),Raw_NBP!R:R,Raw_NBP!S:S,"") -> 525.1 | O63: =_xlfn.NUMBERVALUE(H63,".",",") -> 3668.51

Sheet Returns
F4: Date | G4: Wig20 | H4: Wig20 Daily return | I4: Wig20 Weekly return | J4: Wig20 MTD | K4: Wig20 Vol 20d | L4: Wig20 Peak | M4: Wig20 Drawdown | R4: Date | S4: mWig40 | T4: mWig40 Daily return | U4: mWig40 Weekly return | V4: mWig40 MTD | W4: mWig40 Vol 20d | X4: mWig40 Peak | Y4: mWig40 Drawdown | AE4: Date | AF4: sWig80 | AG4: sWig80 Daily return | AH4: sWig80 Weekly return | AI4: sWig80 MTD | AJ4: sWig20 Vol 20d | AK4: sWig80 Peak | AL4: sWig80 Drawdown | AQ4: Date | AR4: USDPLN | AS4: USDPLN Daily return | AT4: USDPLN Weekly return | AU4: USDPLN MTD | AV4: USDPLN Vol 20d | AW4: USDPLN Peak | AX4: USDPLN Drawdown | BC4: Date | BD4: EURPLN | BE4: EURPLN Daily return | BF4: EURPLN Weekly return | BG4: EURPLN MTD | BH4: EURPLN Vol 20d | BI4: EURPLN Peak | BJ4: EURPLN Drawdown | BO4: Date | BP4: GoldPLN | BQ4: GoldPLN Daily return | BR4: GoldPLN Weekly return | BS4: GoldPLN MTD | BT4: GoldPLN Vol 20d | BU4: GoldPLN Peak | BV4: GoldPLN Drawdown
F5: =Clean_Data!G4 -> 46087 | G5: =Clean_Data!H4 -> 3262.33 | J5: =G5/_xlfn.XLOOKUP(DATE(YEAR(F5),MONTH(F5),1),$F:$F,$G:$G,"",1)-1 -> 0 | L5: =G5 -> 3262.33 | M5: =G5/L5-1 -> 0 | R5: =Clean_Data!G4 -> 46087 | S5: =Clean_Data!I4 -> 8516.38 | V5: =S5/_xlfn.XLOOKUP(DATE(YEAR(R5),MONTH(R5),1),$R:$R,$S:$S,"",1)-1 -> 0 | X5: =S5 -> 8516.38 | Y5: =S5/X5-1 -> 0 | AE5: =Clean_Data!G4 -> 46087 | AF5: =Clean_Data!J4 -> 30658.34 | AI5: =AF5/_xlfn.XLOOKUP(DATE(YEAR(AE5),MONTH(AE5),1),$AE:$AE,$AF:$AF,"",1)-1 -> 0 | AK5: =AF5 -> 30658.34 | AL5: =AF5/AK5-1 -> 0 | AQ5: =Clean_Data!G4 -> 46087 | AR5: =Clean_Data!K4 -> 3.6962 | AU5: =AR5/_xlfn.XLOOKUP(DATE(YEAR(AQ5),MONTH(AE5),1),$AQ:$AQ,$AR:$AR,"",1)-1 -> 0 | AW5: =AR5 -> 3.6962 | AX5: =AR5/AW5-1 -> 0 | BC5: =Clean_Data!G4 -> 46087 | BD5: =Clean_Data!L4 -> 4.2782 | BG5: =BD5/_xlfn.XLOOKUP(DATE(YEAR(BC5),MONTH(AE5),1),$BC:$BC,$BD:$BD,"",1)-1 -> 0 | BI5: =BD5 -> 4.2782 | BJ5: =BD5/BI5-1 -> 0 | BO5: =Clean_Data!G4 -> 46087 | BP5: =Clean_Data!M4 -> 609.99 | BS5: =BP5/_xlfn.XLOOKUP(DATE(YEAR(BO5),MONTH(AE5),1),$BO:$BO,$BP:$BP,"",1)-1 -> 0 | BU5: =BP5 -> 609.99 | BV5: =BP5/BU5-1 -> 0
F6: =Clean_Data!G5 -> 46090 | G6: =Clean_Data!H5 -> 3256.8 | H6: =G6/G5-1 -> -0.0016951075 | J6: =G6/_xlfn.XLOOKUP(DATE(YEAR(F6),MONTH(F6),1),$F:$F,$G:$G,"",1)-1 -> -0.0016951075 | L6: =IF(G6>L5,G6,L5) -> 3262.33 | M6: =G6/L6-1 -> -0.0016951075 | R6: =Clean_Data!G5 -> 46090 | S6: =Clean_Data!I5 -> 8474.65 | T6: =S6/S5-1 -> -0.0048999692 | V6: =S6/_xlfn.XLOOKUP(DATE(YEAR(R6),MONTH(R6),1),$R:$R,$S:$S,"",1)-1 -> -0.0048999692 | X6: =IF(S6>X5,S6,X5) -> 8516.38 | Y6: =S6/X6-1 -> -0.0048999692 | AE6: =Clean_Data!G5 -> 46090 | AF6: =Clean_Data!J5 -> 30384.66 | AG6: =AF6/AF5-1 -> -0.0089267716 | AI6: =AF6/_xlfn.XLOOKUP(DATE(YEAR(AE6),MONTH(AE6),1),$AE:$AE,$AF:$AF,"",1)-1 -> -0.0089267716 | AK6: =IF(AF6>AK5,AF6,AK5) -> 30658.34 | AL6: =AF6/AK6-1 -> -0.0089267716 | AQ6: =Clean_Data!G5 -> 46090 | AR6: =Clean_Data!K5 -> 3.7075 | AS6: =AR6/AR5-1 -> 0.0030571939 | AU6: =AR6/_xlfn.XLOOKUP(DATE(YEAR(AQ6),MONTH(AE6),1),$AQ:$AQ,$AR:$AR,"",1)-1 -> 0.0030571939 | AW6: =IF(AR6>AW5,AR6,AW5) -> 3.7075 | AX6: =AR6/AW6-1 -> 0 | BC6: =Clean_Data!G5 -> 46090 | BD6: =Clean_Data!L5 -> 4.2836 | BE6: =BD6/BD5-1 -> 0.0012622131 | BG6: =BD6/_xlfn.XLOOKUP(DATE(YEAR(BC6),MONTH(AE6),1),$BC:$BC,$BD:$BD,"",1)-1 -> 0.0012622131 | BI6: =IF(BD6>BI5,BD6,BI5) -> 4.2836 | BJ6: =BD6/BI6-1 -> 0 | BO6: =Clean_Data!G5 -> 46090 | BP6: =Clean_Data!M5 -> 604.25 | BQ6: =BP6/BP5-1 -> -0.0094099903 | BS6: =BP6/_xlfn.XLOOKUP(DATE(YEAR(BO6),MONTH(AE6),1),$BO:$BO,$BP:$BP,"",1)-1 -> -0.0094099903 | BU6: =IF(BP6>BU5,BP6,BU5) -> 609.99 | BV6: =BP6/BU6-1 -> -0.0094099903
F7: =Clean_Data!G6 -> 46091 | G7: =Clean_Data!H6 -> 3327.28 | H7: =G7/G6-1 -> 0.021640874 | J7: =G7/_xlfn.XLOOKUP(DATE(YEAR(F7),MONTH(F7),1),$F:$F,$G:$G,"",1)-1 -> 0.019909083 | L7: =IF(G7>L6,G7,L6) -> 3327.28 | M7: =G7/L7-1 -> 0 | R7: =Clean_Data!G6 -> 46091 | S7: =Clean_Data!I6 -> 8578.78 | T7: =S7/S6-1 -> 0.012287233 | V7: =S7/_xlfn.XLOOKUP(DATE(YEAR(R7),MONTH(R7),1),$R:$R,$S:$S,"",1)-1 -> 0.0073270568 | X7: =IF(S7>X6,S7,X6) -> 8578.78 | Y7: =S7/X7-1 -> 0 | AE7: =Clean_Data!G6 -> 46091 | AF7: =Clean_Data!J6 -> 30686.76 | AG7: =AF7/AF6-1 -> 0.009942517 | AI7: =AF7/_xlfn.XLOOKUP(DATE(YEAR(AE7),MONTH(AE7),1),$AE:$AE,$AF:$AF,"",1)-1 -> 0.00092699083 | AK7: =IF(AF7>AK6,AF7,AK6) -> 30686.76 | AL7: =AF7/AK7-1 -> 0 | AQ7: =Clean_Data!G6 -> 46091 | AR7: =Clean_Data!K6 -> 3.6523 | AS7: =AR7/AR6-1 -> -0.014888739 | AU7: =AR7/_xlfn.XLOOKUP(DATE(YEAR(AQ7),MONTH(AE7),1),$AQ:$AQ,$AR:$AR,"",1)-1 -> -0.011877063 | AW7: =IF(AR7>AW6,AR7,AW6) -> 3.7075 | AX7: =AR7/AW7-1 -> -0.014888739 | BC7: =Clean_Data!G6 -> 46091 | BD7: =Clean_Data!L6 -> 4.2555 | BE7: =BD7/BD6-1 -> -0.0065599029 | BG7: =BD7/_xlfn.XLOOKUP(DATE(YEAR(BC7),MONTH(AE7),1),$BC:$BC,$BD:$BD,"",1)-1 -> -0.0053059698 | BI7: =IF(BD7>BI6,BD7,BI6) -> 4.2836 | BJ7: =BD7/BI7-1 -> -0.0065599029 | BO7: =Clean_Data!G6 -> 46091 | BP7: =Clean_Data!M6 -> 608.44 | BQ7: =BP7/BP6-1 -> 0.006934216 | BS7: =BP7/_xlfn.XLOOKUP(DATE(YEAR(BO7),MONTH(AE7),1),$BO:$BO,$BP:$BP,"",1)-1 -> -0.0025410253 | BU7: =IF(BP7>BU6,BP7,BU6) -> 609.99 | BV7: =BP7/BU7-1 -> -0.0025410253
F8: =Clean_Data!G7 -> 46092 | G8: =Clean_Data!H7 -> 3312.71 | H8: =G8/G7-1 -> -0.0043789522 | J8: =G8/_xlfn.XLOOKUP(DATE(YEAR(F8),MONTH(F8),1),$F:$F,$G:$G,"",1)-1 -> 0.01544295 | L8: =IF(G8>L7,G8,L7) -> 3327.28 | M8: =G8/L8-1 -> -0.0043789522 | R8: =Clean_Data!G7 -> 46092 | S8: =Clean_Data!I7 -> 8472.15 | T8: =S8/S7-1 -> -0.012429506 | V8: =S8/_xlfn.XLOOKUP(DATE(YEAR(R8),MONTH(R8),1),$R:$R,$S:$S,"",1)-1 -> -0.0051935212 | X8: =IF(S8>X7,S8,X7) -> 8578.78 | Y8: =S8/X8-1 -> -0.012429506 | AE8: =Clean_Data!G7 -> 46092 | AF8: =Clean_Data!J7 -> 30604.91 | AG8: =AF8/AF7-1 -> -0.0026672741 | AI8: =AF8/_xlfn.XLOOKUP(DATE(YEAR(AE8),MONTH(AE8),1),$AE:$AE,$AF:$AF,"",1)-1 -> -0.0017427558 | AK8: =IF(AF8>AK7,AF8,AK7) -> 30686.76 | AL8: =AF8/AK8-1 -> -0.0026672741 | AQ8: =Clean_Data!G7 -> 46092 | AR8: =Clean_Data!K7 -> 3.687 | AS8: =AR8/AR7-1 -> 0.0095008625 | AU8: =AR8/_xlfn.XLOOKUP(DATE(YEAR(AQ8),MONTH(AE8),1),$AQ:$AQ,$AR:$AR,"",1)-1 -> -0.0024890428 | AW8: =IF(AR8>AW7,AR8,AW7) -> 3.7075 | AX8: =AR8/AW8-1 -> -0.0055293324 | BC8: =Clean_Data!G7 -> 46092 | BD8: =Clean_Data!L7 -> 4.274 | BE8: =BD8/BD7-1 -> 0.0043473152 | BG8: =BD8/_xlfn.XLOOKUP(DATE(YEAR(BC8),MONTH(AE8),1),$BC:$BC,$BD:$BD,"",1)-1 -> -0.00098172128 | BI8: =IF(BD8>BI7,BD8,BI7) -> 4.2836 | BJ8: =BD8/BI8-1 -> -0.0022411056 | BO8: =Clean_Data!G7 -> 46092 | BP8: =Clean_Data!M7 -> 608.47 | BQ8: =BP8/BP7-1 -> 4.9306423e-05 | BS8: =BP8/_xlfn.XLOOKUP(DATE(YEAR(BO8),MONTH(AE8),1),$BO:$BO,$BP:$BP,"",1)-1 -> -0.0024918441 | BU8: =IF(BP8>BU7,BP8,BU7) -> 609.99 | BV8: =BP8/BU8-1 -> -0.0024918441
F9: =Clean_Data!G8 -> 46093 | G9: =Clean_Data!H8 -> 3291.27 | H9: =G9/G8-1 -> -0.0064720425 | J9: =G9/_xlfn.XLOOKUP(DATE(YEAR(F9),MONTH(F9),1),$F:$F,$G:$G,"",1)-1 -> 0.0088709603 | L9: =IF(G9>L8,G9,L8) -> 3327.28 | M9: =G9/L9-1 -> -0.010822654 | R9: =Clean_Data!G8 -> 46093 | S9: =Clean_Data!I8 -> 8357.95 | T9: =S9/S8-1 -> -0.013479459 | V9: =S9/_xlfn.XLOOKUP(DATE(YEAR(R9),MONTH(R9),1),$R:$R,$S:$S,"",1)-1 -> -0.018602975 | X9: =IF(S9>X8,S9,X8) -> 8578.78 | Y9: =S9/X9-1 -> -0.025741422 | AE9: =Clean_Data!G8 -> 46093 | AF9: =Clean_Data!J8 -> 30349.83 | AG9: =AF9/AF8-1 -> -0.0083346104 | AI9: =AF9/_xlfn.XLOOKUP(DATE(YEAR(AE9),MONTH(AE9),1),$AE:$AE,$AF:$AF,"",1)-1 -> -0.010062841 | AK9: =IF(AF9>AK8,AF9,AK8) -> 30686.76 | AL9: =AF9/AK9-1 -> -0.010979654 | AQ9: =Clean_Data!G8 -> 46093 | AR9: =Clean_Data!K8 -> 3.6878 | AS9: =AR9/AR8-1 -> 0.00021697857 | AU9: =AR9/_xlfn.XLOOKUP(DATE(YEAR(AQ9),MONTH(AE9),1),$AQ:$AQ,$AR:$AR,"",1)-1 -> -0.0022726043 | AW9: =IF(AR9>AW8,AR9,AW8) -> 3.7075 | AX9: =AR9/AW9-1 -> -0.0053135536 | BC9: =Clean_Data!G8 -> 46093 | BD9: =Clean_Data!L8 -> 4.2629 | BE9: =BD9/BD8-1 -> -0.0025970987 | BG9: =BD9/_xlfn.XLOOKUP(DATE(YEAR(BC9),MONTH(AE9),1),$BC:$BC,$BD:$BD,"",1)-1 -> -0.0035762704 | BI9: =IF(BD9>BI8,BD9,BI8) -> 4.2836 | BJ9: =BD9/BI9-1 -> -0.004832384 | BO9: =Clean_Data!G8 -> 46093 | BP9: =Clean_Data!M8 -> 614.84 | BQ9: =BP9/BP8-1 -> 0.010468881 | BS9: =BP9/_xlfn.XLOOKUP(DATE(YEAR(BO9),MONTH(AE9),1),$BO:$BO,$BP:$BP,"",1)-1 -> 0.00795095 | BU9: =IF(BP9>BU8,BP9,BU8) -> 614.84 | BV9: =BP9/BU9-1 -> 0
F10: =Clean_Data!G9 -> 46094 | G10: =Clean_Data!H9 -> 3274.54 | H10: =G10/G9-1 -> -0.0050831442 | I10: =G10/G5-1 -> 0.0037427238 | J10: =G10/_xlfn.XLOOKUP(DATE(YEAR(F10),MONTH(F10),1),$F:$F,$G:$G,"",1)-1 -> 0.0037427238 | L10: =IF(G10>L9,G10,L9) -> 3327.28 | M10: =G10/L10-1 -> -0.015850785 | R10: =Clean_Data!G9 -> 46094 | S10: =Clean_Data!I9 -> 8361.59 | T10: =S10/S9-1 -> 0.00043551349 | U10: =S10/S5-1 -> -0.018175563 | V10: =S10/_xlfn.XLOOKUP(DATE(YEAR(R10),MONTH(R10),1),$R:$R,$S:$S,"",1)-1 -> -0.018175563 | X10: =IF(S10>X9,S10,X9) -> 8578.78 | Y10: =S10/X10-1 -> -0.02531712 | AE10: =Clean_Data!G9 -> 46094 | AF10: =Clean_Data!J9 -> 30235.7 | AG10: =AF10/AF9-1 -> -0.0037604823 | AH10: =AF10/AF5-1 -> -0.013785482 | AI10: =AF10/_xlfn.XLOOKUP(DATE(YEAR(AE10),MONTH(AE10),1),$AE:$AE,$AF:$AF,"",1)-1 -> -0.013785482 | AK10: =IF(AF10>AK9,AF10,AK9) -> 30686.76 | AL10: =AF10/AK10-1 -> -0.014698847 | AQ10: =Clean_Data!G9 -> 46094 | AR10: =Clean_Data!K9 -> 3.7277 | AS10: =AR10/AR9-1 -> 0.010819459 | AT10: =AR10/AR5-1 -> 0.0085222661 | AU10: =AR10/_xlfn.XLOOKUP(DATE(YEAR(AQ10),MONTH(AE10),1),$AQ:$AQ,$AR:$AR,"",1)-1 -> 0.0085222661 | AW10: =IF(AR10>AW9,AR10,AW9) -> 3.7277 | AX10: =AR10/AW10-1 -> 0 | BC10: =Clean_Data!G9 -> 46094 | BD10: =Clean_Data!L9 -> 4.2693 | BE10: =BD10/BD9-1 -> 0.0015013254 | BF10: =BD10/BD5-1 -> -0.0020803142 | BG10: =BD10/_xlfn.XLOOKUP(DATE(YEAR(BC10),MONTH(AE10),1),$BC:$BC,$BD:$BD,"",1)-1 -> -0.0020803142 | BI10: =IF(BD10>BI9,BD10,BI9) -> 4.2836 | BJ10: =BD10/BI10-1 -> -0.0033383136 | BO10: =Clean_Data!G9 -> 46094 | BP10: =Clean_Data!M9 -> 615.05 | BQ10: =BP10/BP9-1 -> 0.00034155227 | BR10: =BP10/BP5-1 -> 0.008295218 | BS10: =BP10/_xlfn.XLOOKUP(DATE(YEAR(BO10),MONTH(AE10),1),$BO:$BO,$BP:$BP,"",1)-1 -> 0.008295218 | BU10: =IF(BP10>BU9,BP10,BU9) -> 615.05 | BV10: =BP10/BU10-1 -> 0
F11: =Clean_Data!G10 -> 46097 | G11: =Clean_Data!H10 -> 3292.46 | H11: =G11/G10-1 -> 0.0054725244 | I11: =G11/G6-1 -> 0.010949398 | J11: =G11/_xlfn.XLOOKUP(DATE(YEAR(F11),MONTH(F11),1),$F:$F,$G:$G,"",1)-1 -> 0.0092357303 | L11: =IF(G11>L10,G11,L10) -> 3327.28 | M11: =G11/L11-1 -> -0.010465004 | R11: =Clean_Data!G10 -> 46097 | S11: =Clean_Data!I10 -> 8361.63 | T11: =S11/S10-1 -> 4.7837792e-06 | U11: =S11/S6-1 -> -0.013336244 | V11: =S11/_xlfn.XLOOKUP(DATE(YEAR(R11),MONTH(R11),1),$R:$R,$S:$S,"",1)-1 -> -0.018170866 | X11: =IF(S11>X10,S11,X10) -> 8578.78 | Y11: =S11/X11-1 -> -0.025312457 | AE11: =Clean_Data!G10 -> 46097 | AF11: =Clean_Data!J10 -> 30233.82 | AG11: =AF11/AF10-1 -> -6.2178154e-05 | AH11: =AF11/AF6-1 -> -0.0049643471 | AI11: =AF11/_xlfn.XLOOKUP(DATE(YEAR(AE11),MONTH(AE11),1),$AE:$AE,$AF:$AF,"",1)-1 -> -0.013846803 | AK11: =IF(AF11>AK10,AF11,AK10) -> 30686.76 | AL11: =AF11/AK11-1 -> -0.014760112 | AQ11: =Clean_Data!G10 -> 46097 | AR11: =Clean_Data!K10 -> 3.7287 | AS11: =AR11/AR10-1 -> 0.00026826193 | AT11: =AR11/AR6-1 -> 0.0057181389 | AU11: =AR11/_xlfn.XLOOKUP(DATE(YEAR(AQ11),MONTH(AE11),1),$AQ:$AQ,$AR:$AR,"",1)-1 -> 0.0087928142 | AW11: =IF(AR11>AW10,AR11,AW10) -> 3.7287 | AX11: =AR11/AW11-1 -> 0 | BC11: =Clean_Data!G10 -> 46097 | BD11: =Clean_Data!L10 -> 4.2694 | BE11: =BD11/BD10-1 -> 2.3423044e-05 | BF11: =BD11/BD6-1 -> -0.0033149687 | BG11: =BD11/_xlfn.XLOOKUP(DATE(YEAR(BC11),MONTH(AE11),1),$BC:$BC,$BD:$BD,"",1)-1 -> -0.0020569398 | BI11: =IF(BD11>BI10,BD11,BI10) -> 4.2836 | BJ11: =BD11/BI11-1 -> -0.0033149687 | BO11: =Clean_Data!G10 -> 46097 | BP11: =Clean_Data!M10 -> 609.89 | BQ11: =BP11/BP10-1 -> -0.0083895618 | BR11: =BP11/BP6-1 -> 0.009333885 | BS11: =BP11/_xlfn.XLOOKUP(DATE(YEAR(BO11),MONTH(AE11),1),$BO:$BO,$BP:$BP,"",1)-1 -> -0.00016393711 | BU11: =IF(BP11>BU10,BP11,BU10) -> 615.05 | BV11: =BP11/BU11-1 -> -0.0083895618
F12: =Clean_Data!G11 -> 46098 | G12: =Clean_Data!H11 -> 3359.96 | H12: =G12/G11-1 -> 0.020501388 | I12: =G12/G7-1 -> 0.0098218365 | J12: =G12/_xlfn.XLOOKUP(DATE(YEAR(F12),MONTH(F12),1),$F:$F,$G:$G,"",1)-1 -> 0.029926464 | L12: =IF(G12>L11,G12,L11) -> 3359.96 | M12: =G12/L12-1 -> 0 | R12: =Clean_Data!G11 -> 46098 | S12: =Clean_Data!I11 -> 8623.55 | T12: =S12/S11-1 -> 0.031324036 | U12: =S12/S7-1 -> 0.0052186908 | V12: =S12/_xlfn.XLOOKUP(DATE(YEAR(R12),MONTH(R12),1),$R:$R,$S:$S,"",1)-1 -> 0.012583985 | X12: =IF(S12>X11,S12,X11) -> 8623.55 | Y12: =S12/X12-1 -> 0 | AE12: =Clean_Data!G11 -> 46098 | AF12: =Clean_Data!J11 -> 30485.61 | AG12: =AF12/AF11-1 -> 0.0083280909 | AH12: =AF12/AF7-1 -> -0.0065549442 | AI12: =AF12/_xlfn.XLOOKUP(DATE(YEAR(AE12),MONTH(AE12),1),$AE:$AE,$AF:$AF,"",1)-1 -> -0.0056340298 | AK12: =IF(AF12>AK11,AF12,AK11) -> 30686.76 | AL12: =AF12/AK12-1 -> -0.0065549442 | AQ12: =Clean_Data!G11 -> 46098 | AR12: =Clean_Data!K11 -> 3.7046 | AS12: =AR12/AR11-1 -> -0.0064633787 | AT12: =AR12/AR7-1 -> 0.014319744 | AU12: =AR12/_xlfn.XLOOKUP(DATE(YEAR(AQ12),MONTH(AE12),1),$AQ:$AQ,$AR:$AR,"",1)-1 -> 0.0022726043 | AW12: =IF(AR12>AW11,AR12,AW11) -> 3.7287 | AX12: =AR12/AW12-1 -> -0.0064633787 | BC12: =Clean_Data!G11 -> 46098 | BD12: =Clean_Data!L11 -> 4.2666 | BE12: =BD12/BD11-1 -> -0.00065582986 | BF12: =BD12/BD7-1 -> 0.0026083891 | BG12: =BD12/_xlfn.XLOOKUP(DATE(YEAR(BC12),MONTH(AE12),1),$BC:$BC,$BD:$BD,"",1)-1 -> -0.0027114207 | BI12: =IF(BD12>BI11,BD12,BI11) -> 4.2836 | BJ12: =BD12/BI12-1 -> -0.0039686245 | BO12: =Clean_Data!G11 -> 46098 | BP12: =Clean_Data!M11 -> 596.33 | BQ12: =BP12/BP11-1 -> -0.022233518 | BR12: =BP12/BP7-1 -> -0.019903359 | BS12: =BP12/_xlfn.XLOOKUP(DATE(YEAR(BO12),MONTH(AE12),1),$BO:$BO,$BP:$BP,"",1)-1 -> -0.02239381 | BU12: =IF(BP12>BU11,BP12,BU11) -> 615.05 | BV12: =BP12/BU12-1 -> -0.03043655
F13: =Clean_Data!G12 -> 46099 | G13: =Clean_Data!H12 -> 3338.2 | H13: =G13/G12-1 -> -0.0064762676 | I13: =G13/G8-1 -> 0.0076946065 | J13: =G13/_xlfn.XLOOKUP(DATE(YEAR(F13),MONTH(F13),1),$F:$F,$G:$G,"",1)-1 -> 0.023256384 | L13: =IF(G13>L12,G13,L12) -> 3359.96 | M13: =G13/L13-1 -> -0.0064762676 | R13: =Clean_Data!G12 -> 46099 | S13: =Clean_Data!I12 -> 8537.47 | T13: =S13/S12-1 -> -0.009981968 | U13: =S13/S8-1 -> 0.0077099674 | V13: =S13/_xlfn.XLOOKUP(DATE(YEAR(R13),MONTH(R13),1),$R:$R,$S:$S,"",1)-1 -> 0.0024764043 | X13: =IF(S13>X12,S13,X12) -> 8623.55 | Y13: =S13/X13-1 -> -0.009981968 | AE13: =Clean_Data!G12 -> 46099 | AF13: =Clean_Data!J12 -> 30315.52 | AG13: =AF13/AF12-1 -> -0.0055793537 | AH13: =AF13/AF8-1 -> -0.0094556723 | AI13: =AF13/_xlfn.XLOOKUP(DATE(YEAR(AE13),MONTH(AE13),1),$AE:$AE,$AF:$AF,"",1)-1 -> -0.011181949 | AK13: =IF(AF13>AK12,AF13,AK12) -> 30686.76 | AL13: =AF13/AK13-1 -> -0.012097726 | AQ13: =Clean_Data!G12 -> 46099 | AR13: =Clean_Data!K12 -> 3.693 | AS13: =AR13/AR12-1 -> -0.0031312422 | AT13: =AR13/AR8-1 -> 0.0016273393 | AU13: =AR13/_xlfn.XLOOKUP(DATE(YEAR(AQ13),MONTH(AE13),1),$AQ:$AQ,$AR:$AR,"",1)-1 -> -0.00086575402 | AW13: =IF(AR13>AW12,AR13,AW12) -> 3.7287 | AX13: =AR13/AW13-1 -> -0.0095743825 | BC13: =Clean_Data!G12 -> 46099 | BD13: =Clean_Data!L12 -> 4.2613 | BE13: =BD13/BD12-1 -> -0.0012422069 | BF13: =BD13/BD8-1 -> -0.0029714553 | BG13: =BD13/_xlfn.XLOOKUP(DATE(YEAR(BC13),MONTH(AE13),1),$BC:$BC,$BD:$BD,"",1)-1 -> -0.0039502595 | BI13: =IF(BD13>BI12,BD13,BI12) -> 4.2836 | BJ13: =BD13/BI13-1 -> -0.0052059016 | BO13: =Clean_Data!G12 -> 46099 | BP13: =Clean_Data!M12 -> 596.66 | BQ13: =BP13/BP12-1 -> 0.00055338487 | BR13: =BP13/BP8-1 -> -0.019409338 | BS13: =BP13/_xlfn.XLOOKUP(DATE(YEAR(BO13),MONTH(AE13),1),$BO:$BO,$BP:$BP,"",1)-1 -> -0.021852817 | BU13: =IF(BP13>BU12,BP13,BU12) -> 615.05 | BV13: =BP13/BU13-1 -> -0.029900008
F14: =Clean_Data!G13 -> 46100 | G14: =Clean_Data!H13 -> 3276.57 | H14: =G14/G13-1 -> -0.018462045 | I14: =G14/G9-1 -> -0.004466361 | J14: =G14/_xlfn.XLOOKUP(DATE(YEAR(F14),MONTH(F14),1),$F:$F,$G:$G,"",1)-1 -> 0.0043649784 | L14: =IF(G14>L13,G14,L13) -> 3359.96 | M14: =G14/L14-1 -> -0.024818748 | R14: =Clean_Data!G13 -> 46100 | S14: =Clean_Data!I13 -> 8418.91 | T14: =S14/S13-1 -> -0.013887018 | U14: =S14/S9-1 -> 0.0072936545 | V14: =S14/_xlfn.XLOOKUP(DATE(YEAR(R14),MONTH(R14),1),$R:$R,$S:$S,"",1)-1 -> -0.011445004 | X14: =IF(S14>X13,S14,X13) -> 8623.55 | Y14: =S14/X14-1 -> -0.023730366 | AE14: =Clean_Data!G13 -> 46100 | AF14: =Clean_Data!J13 -> 29835.38 | AG14: =AF14/AF13-1 -> -0.015838092 | AH14: =AF14/AF9-1 -> -0.016950672 | AI14: =AF14/_xlfn.XLOOKUP(DATE(YEAR(AE14),MONTH(AE14),1),$AE:$AE,$AF:$AF,"",1)-1 -> -0.026842941 | AK14: =IF(AF14>AK13,AF14,AK13) -> 30686.76 | AL14: =AF14/AK14-1 -> -0.027744213 | AQ14: =Clean_Data!G13 -> 46100 | AR14: =Clean_Data!K13 -> 3.727 | AS14: =AR14/AR13-1 -> 0.0092066071 | AT14: =AR14/AR9-1 -> 0.010629644 | AU14: =AR14/_xlfn.XLOOKUP(DATE(YEAR(AQ14),MONTH(AE14),1),$AQ:$AQ,$AR:$AR,"",1)-1 -> 0.0083328824 | AW14: =IF(AR14>AW13,AR14,AW13) -> 3.7287 | AX14: =AR14/AW14-1 -> -0.00045592298 | BC14: =Clean_Data!G13 -> 46100 | BD14: =Clean_Data!L13 -> 4.2782 | BE14: =BD14/BD13-1 -> 0.0039659259 | BF14: =BD14/BD9-1 -> 0.003589106 | BG14: =BD14/_xlfn.XLOOKUP(DATE(YEAR(BC14),MONTH(AE14),1),$BC:$BC,$BD:$BD,"",1)-1 -> 0 | BI14: =IF(BD14>BI13,BD14,BI13) -> 4.2836 | BJ14: =BD14/BI14-1 -> -0.0012606219 | BO14: =Clean_Data!G13 -> 46100 | BP14: =Clean_Data!M13 -> 592.62 | BQ14: =BP14/BP13-1 -> -0.0067710254 | BR14: =BP14/BP9-1 -> -0.036139483 | BS14: =BP14/_xlfn.XLOOKUP(DATE(YEAR(BO14),MONTH(AE14),1),$BO:$BO,$BP:$BP,"",1)-1 -> -0.028475877 | BU14: =IF(BP14>BU13,BP14,BU13) -> 615.05 | BV14: =BP14/BU14-1 -> -0.03646858
F15: =Clean_Data!G14 -> 46101 | G15: =Clean_Data!H14 -> 3248.12 | H15: =G15/G14-1 -> -0.0086828604 | I15: =G15/G10-1 -> -0.0080683088 | J15: =G15/_xlfn.XLOOKUP(DATE(YEAR(F15),MONTH(F15),1),$F:$F,$G:$G,"",1)-1 -> -0.0043557825 | L15: =IF(G15>L14,G15,L14) -> 3359.96 | M15: =G15/L15-1 -> -0.033286111 | R15: =Clean_Data!G14 -> 46101 | S15: =Clean_Data!I14 -> 8247.07 | T15: =S15/S14-1 -> -0.020411193 | U15: =S15/S10-1 -> -0.01369596 | V15: =S15/_xlfn.XLOOKUP(DATE(YEAR(R15),MONTH(R15),1),$R:$R,$S:$S,"",1)-1 -> -0.031622591 | X15: =IF(S15>X14,S15,X14) -> 8623.55 | Y15: =S15/X15-1 -> -0.043657195 | AE15: =Clean_Data!G14 -> 46101 | AF15: =Clean_Data!J14 -> 29641.24 | AG15: =AF15/AF14-1 -> -0.0065070396 | AH15: =AF15/AF10-1 -> -0.019660864 | AI15: =AF15/_xlfn.XLOOKUP(DATE(YEAR(AE15),MONTH(AE15),1),$AE:$AE,$AF:$AF,"",1)-1 -> -0.033175312 | AK15: =IF(AF15>AK14,AF15,AK14) -> 30686.76 | AL15: =AF15/AK15-1 -> -0.03407072 | AQ15: =Clean_Data!G14 -> 46101 | AR15: =Clean_Data!K14 -> 3.7032 | AS15: =AR15/AR14-1 -> -0.0063858331 | AT15: =AR15/AR10-1 -> -0.0065724173 | AU15: =AR15/_xlfn.XLOOKUP(DATE(YEAR(AQ15),MONTH(AE15),1),$AQ:$AQ,$AR:$AR,"",1)-1 -> 0.0018938369 | AW15: =IF(AR15>AW14,AR15,AW14) -> 3.7287 | AX15: =AR15/AW15-1 -> -0.0068388446 | BC15: =Clean_Data!G14 -> 46101 | BD15: =Clean_Data!L14 -> 4.2768 | BE15: =BD15/BD14-1 -> -0.00032724043 | BF15: =BD15/BD10-1 -> 0.0017567283 | BG15: =BD15/_xlfn.XLOOKUP(DATE(YEAR(BC15),MONTH(AE15),1),$BC:$BC,$BD:$BD,"",1)-1 -> -0.00032724043 | BI15: =IF(BD15>BI14,BD15,BI14) -> 4.2836 | BJ15: =BD15/BI15-1 -> -0.0015874498 | BO15: =Clean_Data!G14 -> 46101 | BP15: =Clean_Data!M14 -> 562.93 | BQ15: =BP15/BP14-1 -> -0.050099558 | BR15: =BP15/BP10-1 -> -0.084741078 | BS15: =BP15/_xlfn.XLOOKUP(DATE(YEAR(BO15),MONTH(AE15),1),$BO:$BO,$BP:$BP,"",1)-1 -> -0.077148806 | BU15: =IF(BP15>BU14,BP15,BU14) -> 615.05 | BV15: =BP15/BU15-1 -> -0.084741078
F16: =Clean_Data!G15 -> 46104 | G16: =Clean_Data!H15 -> 3268.15 | H16: =G16/G15-1 -> 0.0061666441 | I16: =G16/G11-1 -> -0.0073835369 | J16: =G16/_xlfn.XLOOKUP(DATE(YEAR(F16),MONTH(F16),1),$F:$F,$G:$G,"",1)-1 -> 0.001784001 | L16: =IF(G16>L15,G16,L15) -> 3359.96 | M16: =G16/L16-1 -> -0.02732473 | R16: =Clean_Data!G15 -> 46104 | S16: =Clean_Data!I15 -> 8297.37 | T16: =S16/S15-1 -> 0.0060991358 | U16: =S16/S11-1 -> -0.0076851045 | V16: =S16/_xlfn.XLOOKUP(DATE(YEAR(R16),MONTH(R16),1),$R:$R,$S:$S,"",1)-1 -> -0.025716325 | X16: =IF(S16>X15,S16,X15) -> 8623.55 | Y16: =S16/X16-1 -> -0.03782433 | AE16: =Clean_Data!G15 -> 46104 | AF16: =Clean_Data!J15 -> 29248.18 | AG16: =AF16/AF15-1 -> -0.013260579 | AH16: =AF16/AF11-1 -> -0.032600578 | AI16: =AF16/_xlfn.XLOOKUP(DATE(YEAR(AE16),MONTH(AE16),1),$AE:$AE,$AF:$AF,"",1)-1 -> -0.045995967 | AK16: =IF(AF16>AK15,AF16,AK15) -> 30686.76 | AL16: =AF16/AK16-1 -> -0.046879501 | AQ16: =Clean_Data!G15 -> 46104 | AR16: =Clean_Data!K15 -> 3.7292 | AS16: =AR16/AR15-1 -> 0.0070209548 | AT16: =AR16/AR11-1 -> 0.00013409499 | AU16: =AR16/_xlfn.XLOOKUP(DATE(YEAR(AQ16),MONTH(AE16),1),$AQ:$AQ,$AR:$AR,"",1)-1 -> 0.0089280883 | AW16: =IF(AR16>AW15,AR16,AW15) -> 3.7292 | AX16: =AR16/AW16-1 -> 0 | BC16: =Clean_Data!G15 -> 46104 | BD16: =Clean_Data!L15 -> 4.2867 | BE16: =BD16/BD15-1 -> 0.0023148148 | BF16: =BD16/BD11-1 -> 0.0040520916 | BG16: =BD16/_xlfn.XLOOKUP(DATE(YEAR(BC16),MONTH(AE16),1),$BC:$BC,$BD:$BD,"",1)-1 -> 0.0019868169 | BI16: =IF(BD16>BI15,BD16,BI15) -> 4.2867 | BJ16: =BD16/BI16-1 -> 0 | BO16: =Clean_Data!G15 -> 46104 | BP16: =Clean_Data!M15 -> 555.59 | BQ16: =BP16/BP15-1 -> -0.013038921 | BR16: =BP16/BP11-1 -> -0.089032448 | BS16: =BP16/_xlfn.XLOOKUP(DATE(YEAR(BO16),MONTH(AE16),1),$BO:$BO,$BP:$BP,"",1)-1 -> -0.08918179 | BU16: =IF(BP16>BU15,BP16,BU15) -> 615.05 | BV16: =BP16/BU16-1 -> -0.096675067
F17: =Clean_Data!G16 -> 46105 | G17: =Clean_Data!H16 -> 3241.42 | H17: =G17/G16-1 -> -0.0081789392 | I17: =G17/G12-1 -> -0.035280182 | J17: =G17/_xlfn.XLOOKUP(DATE(YEAR(F17),MONTH(F17),1),$F:$F,$G:$G,"",1)-1 -> -0.0064095294 | L17: =IF(G17>L16,G17,L16) -> 3359.96 | M17: =G17/L17-1 -> -0.035280182 | R17: =Clean_Data!G16 -> 46105 | S17: =Clean_Data!I16 -> 8194.25 | T17: =S17/S16-1 -> -0.012428034 | U17: =S17/S12-1 -> -0.049782282 | V17: =S17/_xlfn.XLOOKUP(DATE(YEAR(R17),MONTH(R17),1),$R:$R,$S:$S,"",1)-1 -> -0.037824757 | X17: =IF(S17>X16,S17,X16) -> 8623.55 | Y17: =S17/X17-1 -> -0.049782282 | AE17: =Clean_Data!G16 -> 46105 | AF17: =Clean_Data!J16 -> 29140.98 | AG17: =AF17/AF16-1 -> -0.0036651853 | AH17: =AF17/AF12-1 -> -0.044107039 | AI17: =AF17/_xlfn.XLOOKUP(DATE(YEAR(AE17),MONTH(AE17),1),$AE:$AE,$AF:$AF,"",1)-1 -> -0.049492569 | AK17: =IF(AF17>AK16,AF17,AK16) -> 30686.76 | AL17: =AF17/AK17-1 -> -0.050372864 | AQ17: =Clean_Data!G16 -> 46105 | AR17: =Clean_Data!K16 -> 3.685 | AS17: =AR17/AR16-1 -> -0.011852408 | AT17: =AR17/AR12-1 -> -0.0052907196 | AU17: =AR17/_xlfn.XLOOKUP(DATE(YEAR(AQ17),MONTH(AE17),1),$AQ:$AQ,$AR:$AR,"",1)-1 -> -0.0030301391 | AW17: =IF(AR17>AW16,AR17,AW16) -> 3.7292 | AX17: =AR17/AW17-1 -> -0.011852408 | BC17: =Clean_Data!G16 -> 46105 | BD17: =Clean_Data!L16 -> 4.2728 | BE17: =BD17/BD16-1 -> -0.0032425875 | BF17: =BD17/BD12-1 -> 0.0014531477 | BG17: =BD17/_xlfn.XLOOKUP(DATE(YEAR(BC17),MONTH(AE17),1),$BC:$BC,$BD:$BD,"",1)-1 -> -0.0012622131 | BI17: =IF(BD17>BI16,BD17,BI16) -> 4.2867 | BJ17: =BD17/BI17-1 -> -0.0032425875 | BO17: =Clean_Data!G16 -> 46105 | BP17: =Clean_Data!M16 -> 509.82 | BQ17: =BP17/BP16-1 -> -0.082380892 | BR17: =BP17/BP12-1 -> -0.14507068 | BS17: =BP17/_xlfn.XLOOKUP(DATE(YEAR(BO17),MONTH(AE17),1),$BO:$BO,$BP:$BP,"",1)-1 -> -0.16421581 | BU17: =IF(BP17>BU16,BP17,BU16) -> 615.05 | BV17: =BP17/BU17-1 -> -0.17109178
F18: =Clean_Data!G17 -> 46106 | G18: =Clean_Data!H17 -> 3312.41 | H18: =G18/G17-1 -> 0.021900895 | I18: =G18/G13-1 -> -0.0077257204 | J18: =G18/_xlfn.XLOOKUP(DATE(YEAR(F18),MONTH(F18),1),$F:$F,$G:$G,"",1)-1 -> 0.015350991 | L18: =IF(G18>L17,G18,L17) -> 3359.96 | M18: =G18/L18-1 -> -0.014151954 | R18: =Clean_Data!G17 -> 46106 | S18: =Clean_Data!I17 -> 8298.55 | T18: =S18/S17-1 -> 0.012728438 | U18: =S18/S13-1 -> -0.027984871 | V18: =S18/_xlfn.XLOOKUP(DATE(YEAR(R18),MONTH(R18),1),$R:$R,$S:$S,"",1)-1 -> -0.025577769 | X18: =IF(S18>X17,S18,X17) -> 8623.55 | Y18: =S18/X18-1 -> -0.037687495 | AE18: =Clean_Data!G17 -> 46106 | AF18: =Clean_Data!J17 -> 29515.4 | AG18: =AF18/AF17-1 -> 0.012848573 | AH18: =AF18/AF13-1 -> -0.026393082 | AI18: =AF18/_xlfn.XLOOKUP(DATE(YEAR(AE18),MONTH(AE18),1),$AE:$AE,$AF:$AF,"",1)-1 -> -0.037279905 | AK18: =IF(AF18>AK17,AF18,AK17) -> 30686.76 | AL18: =AF18/AK18-1 -> -0.038171511 | AQ18: =Clean_Data!G17 -> 46106 | AR18: =Clean_Data!K17 -> 3.6803 | AS18: =AR18/AR17-1 -> -0.001275441 | AT18: =AR18/AR13-1 -> -0.0034389385 | AU18: =AR18/_xlfn.XLOOKUP(DATE(YEAR(AQ18),MONTH(AE18),1),$AQ:$AQ,$AR:$AR,"",1)-1 -> -0.0043017153 | AW18: =IF(AR18>AW17,AR18,AW17) -> 3.7292 | AX18: =AR18/AW18-1 -> -0.013112732 | BC18: =Clean_Data!G17 -> 46106 | BD18: =Clean_Data!L17 -> 4.2692 | BE18: =BD18/BD17-1 -> -0.00084253885 | BF18: =BD18/BD13-1 -> 0.0018538944 | BG18: =BD18/_xlfn.XLOOKUP(DATE(YEAR(BC18),MONTH(AE18),1),$BC:$BC,$BD:$BD,"",1)-1 -> -0.0021036885 | BI18: =IF(BD18>BI17,BD18,BI17) -> 4.2867 | BJ18: =BD18/BI18-1 -> -0.0040823944 | BO18: =Clean_Data!G17 -> 46106 | BP18: =Clean_Data!M17 -> 524.34 | BQ18: =BP18/BP17-1 -> 0.02848064 | BR18: =BP18/BP13-1 -> -0.12120806 | BS18: =BP18/_xlfn.XLOOKUP(DATE(YEAR(BO18),MONTH(AE18),1),$BO:$BO,$BP:$BP,"",1)-1 -> -0.14041214 | BU18: =IF(BP18>BU17,BP18,BU17) -> 615.05 | BV18: =BP18/BU18-1 -> -0.14748394
F19: =Clean_Data!G18 -> 46107 | G19: =Clean_Data!H18 -> 3306.6 | H19: =G19/G18-1 -> -0.0017540099 | I19: =G19/G14-1 -> 0.009165072 | J19: =G19/_xlfn.XLOOKUP(DATE(YEAR(F19),MONTH(F19),1),$F:$F,$G:$G,"",1)-1 -> 0.013570056 | L19: =IF(G19>L18,G19,L18) -> 3359.96 | M19: =G19/L19-1 -> -0.015881141 | R19: =Clean_Data!G18 -> 46107 | S19: =Clean_Data!I18 -> 8273.52 | T19: =S19/S18-1 -> -0.0030161896 | U19: =S19/S14-1 -> -0.017269456 | V19: =S19/_xlfn.XLOOKUP(DATE(YEAR(R19),MONTH(R19),1),$R:$R,$S:$S,"",1)-1 -> -0.028516811 | X19: =IF(S19>X18,S19,X18) -> 8623.55 | Y19: =S19/X19-1 -> -0.040590012 | AE19: =Clean_Data!G18 -> 46107 | AF19: =Clean_Data!J18 -> 29371.5 | AG19: =AF19/AF18-1 -> -0.004875421 | AH19: =AF19/AF14-1 -> -0.015547984 | AI19: =AF19/_xlfn.XLOOKUP(DATE(YEAR(AE19),MONTH(AE19),1),$AE:$AE,$AF:$AF,"",1)-1 -> -0.041973571 | AK19: =IF(AF19>AK18,AF19,AK18) -> 30686.76 | AL19: =AF19/AK19-1 -> -0.04286083 | AQ19: =Clean_Data!G18 -> 46107 | AR19: =Clean_Data!K18 -> 3.6948 | AS19: =AR19/AR18-1 -> 0.0039398962 | AT19: =AR19/AR14-1 -> -0.0086396566 | AU19: =AR19/_xlfn.XLOOKUP(DATE(YEAR(AQ19),MONTH(AE19),1),$AQ:$AQ,$AR:$AR,"",1)-1 -> -0.00037876738 | AW19: =IF(AR19>AW18,AR19,AW18) -> 3.7292 | AX19: =AR19/AW19-1 -> -0.0092244986 | BC19: =Clean_Data!G18 -> 46107 | BD19: =Clean_Data!L18 -> 4.271 | BE19: =BD19/BD18-1 -> 0.00042162466 | BF19: =BD19/BD14-1 -> -0.0016829508 | BG19: =BD19/_xlfn.XLOOKUP(DATE(YEAR(BC19),MONTH(AE19),1),$BC:$BC,$BD:$BD,"",1)-1 -> -0.0016829508 | BI19: =IF(BD19>BI18,BD19,BI18) -> 4.2867 | BJ19: =BD19/BI19-1 -> -0.003662491 | BO19: =Clean_Data!G18 -> 46107 | BP19: =Clean_Data!M18 -> 538.46 | BQ19: =BP19/BP18-1 -> 0.026929092 | BR19: =BP19/BP14-1 -> -0.091390773 | BS19: =BP19/_xlfn.XLOOKUP(DATE(YEAR(BO19),MONTH(AE19),1),$BO:$BO,$BP:$BP,"",1)-1 -> -0.11726422 | BU19: =IF(BP19>BU18,BP19,BU18) -> 615.05 | BV19: =BP19/BU19-1 -> -0.12452646
F20: =Clean_Data!G19 -> 46108 | G20: =Clean_Data!H19 -> 3268.55 | H20: =G20/G19-1 -> -0.011507288 | I20: =G20/G15-1 -> 0.0062897922 | J20: =G20/_xlfn.XLOOKUP(DATE(YEAR(F20),MONTH(F20),1),$F:$F,$G:$G,"",1)-1 -> 0.0019066128 | L20: =IF(G20>L19,G20,L19) -> 3359.96 | M20: =G20/L20-1 -> -0.027205681 | R20: =Clean_Data!G19 -> 46108 | S20: =Clean_Data!I19 -> 8240.93 | T20: =S20/S19-1 -> -0.0039390731 | U20: =S20/S15-1 -> -0.00074450684 | V20: =S20/_xlfn.XLOOKUP(DATE(YEAR(R20),MONTH(R20),1),$R:$R,$S:$S,"",1)-1 -> -0.032343554 | X20: =IF(S20>X19,S20,X19) -> 8623.55 | Y20: =S20/X20-1 -> -0.044369198 | AE20: =Clean_Data!G19 -> 46108 | AF20: =Clean_Data!J19 -> 29055.93 | AG20: =AF20/AF19-1 -> -0.010744089 | AH20: =AF20/AF15-1 -> -0.019746475 | AI20: =AF20/_xlfn.XLOOKUP(DATE(YEAR(AE20),MONTH(AE20),1),$AE:$AE,$AF:$AF,"",1)-1 -> -0.052266692 | AK20: =IF(AF20>AK19,AF20,AK19) -> 30686.76 | AL20: =AF20/AK20-1 -> -0.053144418 | AQ20: =Clean_Data!G19 -> 46108 | AR20: =Clean_Data!K19 -> 3.7206 | AS20: =AR20/AR19-1 -> 0.0069827866 | AT20: =AR20/AR15-1 -> 0.004698639 | AU20: =AR20/_xlfn.XLOOKUP(DATE(YEAR(AQ20),MONTH(AE20),1),$AQ:$AQ,$AR:$AR,"",1)-1 -> 0.0066013744 | AW20: =IF(AR20>AW19,AR20,AW19) -> 3.7292 | AX20: =AR20/AW20-1 -> -0.0023061246 | BC20: =Clean_Data!G19 -> 46108 | BD20: =Clean_Data!L19 -> 4.2858 | BE20: =BD20/BD19-1 -> 0.0034652306 | BF20: =BD20/BD15-1 -> 0.0021043771 | BG20: =BD20/_xlfn.XLOOKUP(DATE(YEAR(BC20),MONTH(AE20),1),$BC:$BC,$BD:$BD,"",1)-1 -> 0.001776448 | BI20: =IF(BD20>BI19,BD20,BI19) -> 4.2867 | BJ20: =BD20/BI20-1 -> -0.00020995171 | BO20: =Clean_Data!G19 -> 46108 | BP20: =Clean_Data!M19 -> 525.4 | BQ20: =BP20/BP19-1 -> -0.024254355 | BR20: =BP20/BP15-1 -> -0.066669035 | BS20: =BP20/_xlfn.XLOOKUP(DATE(YEAR(BO20),MONTH(AE20),1),$BO:$BO,$BP:$BP,"",1)-1 -> -0.1386744 | BU20: =IF(BP20>BU19,BP20,BU19) -> 615.05 | BV20: =BP20/BU20-1 -> -0.14576051
F21: =Clean_Data!G20 -> 46111 | G21: =Clean_Data!H20 -> 3283.06 | H21: =G21/G20-1 -> 0.0044392774 | I21: =G21/G16-1 -> 0.0045622141 | J21: =G21/_xlfn.XLOOKUP(DATE(YEAR(F21),MONTH(F21),1),$F:$F,$G:$G,"",1)-1 -> 0.0063543541 | L21: =IF(G21>L20,G21,L20) -> 3359.96 | M21: =G21/L21-1 -> -0.022887177 | R21: =Clean_Data!G20 -> 46111 | S21: =Clean_Data!I20 -> 8288.88 | T21: =S21/S20-1 -> 0.0058185181 | U21: =S21/S16-1 -> -0.0010232158 | V21: =S21/_xlfn.XLOOKUP(DATE(YEAR(R21),MONTH(R21),1),$R:$R,$S:$S,"",1)-1 -> -0.026713228 | X21: =IF(S21>X20,S21,X20) -> 8623.55 | Y21: =S21/X21-1 -> -0.038808843 | AE21: =Clean_Data!G20 -> 46111 | AF21: =Clean_Data!J20 -> 29017.61 | AG21: =AF21/AF20-1 -> -0.0013188358 | AH21: =AF21/AF16-1 -> -0.0078832256 | AI21: =AF21/_xlfn.XLOOKUP(DATE(YEAR(AE21),MONTH(AE21),1),$AE:$AE,$AF:$AF,"",1)-1 -> -0.053516596 | AK21: =IF(AF21>AK20,AF21,AK20) -> 30686.76 | AL21: =AF21/AK21-1 -> -0.054393165 | AQ21: =Clean_Data!G20 -> 46111 | AR21: =Clean_Data!K20 -> 3.7257 | AS21: =AR21/AR20-1 -> 0.0013707467 | AT21: =AR21/AR16-1 -> -0.0009385391 | AU21: =AR21/_xlfn.XLOOKUP(DATE(YEAR(AQ21),MONTH(AE21),1),$AQ:$AQ,$AR:$AR,"",1)-1 -> 0.0079811699 | AW21: =IF(AR21>AW20,AR21,AW20) -> 3.7292 | AX21: =AR21/AW21-1 -> -0.0009385391 | BC21: =Clean_Data!G20 -> 46111 | BD21: =Clean_Data!L20 -> 4.2832 | BE21: =BD21/BD20-1 -> -0.00060665453 | BF21: =BD21/BD16-1 -> -0.00081647888 | BG21: =BD21/_xlfn.XLOOKUP(DATE(YEAR(BC21),MONTH(AE21),1),$BC:$BC,$BD:$BD,"",1)-1 -> 0.0011687158 | BI21: =IF(BD21>BI20,BD21,BI20) -> 4.2867 | BJ21: =BD21/BI21-1 -> -0.00081647888 | BO21: =Clean_Data!G20 -> 46111 | BP21: =Clean_Data!M20 -> 529.66 | BQ21: =BP21/BP20-1 -> 0.0081081081 | BR21: =BP21/BP16-1 -> -0.046671106 | BS21: =BP21/_xlfn.XLOOKUP(DATE(YEAR(BO21),MONTH(AE21),1),$BO:$BO,$BP:$BP,"",1)-1 -> -0.13169068 | BU21: =IF(BP21>BU20,BP21,BU20) -> 615.05 | BV21: =BP21/BU21-1 -> -0.13883424
... F24: =Clean_Data!G23 -> 46114 | G24: =Clean_Data!H23 -> 3433.65 | H24: =G24/G23-1 -> 0.0090304797 | I24: =G24/G19-1 -> 0.038423154 | J24: =G24/_xlfn.XLOOKUP(DATE(YEAR(F24),MONTH(F24),1),$F:$F,$G:$G,"",1)-1 -> 0.0090304797 | L24: =IF(G24>L23,G24,L23) -> 3433.65 | M24: =G24/L24-1 -> 0 | R24: =Clean_Data!G23 -> 46114 | S24: =Clean_Data!I23 -> 8652.4 | T24: =S24/S23-1 -> 0.0083512611 | U24: =S24/S19-1 -> 0.045794293 | V24: =S24/_xlfn.XLOOKUP(DATE(YEAR(R24),MONTH(R24),1),$R:$R,$S:$S,"",1)-1 -> 0.0083512611 | X24: =IF(S24>X23,S24,X23) -> 8652.4 | Y24: =S24/X24-1 -> 0 | AE24: =Clean_Data!G23 -> 46114 | AF24: =Clean_Data!J23 -> 29881.32 | AG24: =AF24/AF23-1 -> -0.00092447182 | AH24: =AF24/AF19-1 -> 0.017357643 | AI24: =AF24/_xlfn.XLOOKUP(DATE(YEAR(AE24),MONTH(AE24),1),$AE:$AE,$AF:$AF,"",1)-1 -> -0.00092447182 | AK24: =IF(AF24>AK23,AF24,AK23) -> 30686.76 | AL24: =AF24/AK24-1 -> -0.02624715 | AQ24: =Clean_Data!G23 -> 46114 | AR24: =Clean_Data!K23 -> 3.7195 | AS24: =AR24/AR23-1 -> 0.0060315915 | AT24: =AR24/AR19-1 -> 0.0066850709 | AU24: =AR24/_xlfn.XLOOKUP(DATE(YEAR(AQ24),MONTH(AE24),1),$AQ:$AQ,$AR:$AR,"",1)-1 -> 0.0060315915 | AW24: =IF(AR24>AW23,AR24,AW23) -> 3.7408 | AX24: =AR24/AW24-1 -> -0.0056939692 | BC24: =Clean_Data!G23 -> 46114 | BD24: =Clean_Data!L23 -> 4.2869 | BE24: =BD24/BD23-1 -> -0.0001166208 | BF24: =BD24/BD19-1 -> 0.0037227815 | BG24: =BD24/_xlfn.XLOOKUP(DATE(YEAR(BC24),MONTH(AE24),1),$BC:$BC,$BD:$BD,"",1)-1 -> -0.0001166208 | BI24: =IF(BD24>BI23,BD24,BI23) -> 4.2894 | BJ24: =BD24/BI24-1 -> -0.0005828321 | BO24: =Clean_Data!G23 -> 46114 | BP24: =Clean_Data!M23 -> 561.97 | BQ24: =BP24/BP23-1 -> 0.022991226 | BR24: =BP24/BP19-1 -> 0.043661553 | BS24: =BP24/_xlfn.XLOOKUP(DATE(YEAR(BO24),MONTH(AE24),1),$BO:$BO,$BP:$BP,"",1)-1 -> 0.022991226 | BU24: =IF(BP24>BU23,BP24,BU23) -> 615.05 | BV24: =BP24/BU24-1 -> -0.086301927
F25: =Clean_Data!G24 -> 46119 | G25: =Clean_Data!H24 -> 3416.8 | H25: =G25/G24-1 -> -0.0049073144 | I25: =G25/G20-1 -> 0.045356504 | J25: =G25/_xlfn.XLOOKUP(DATE(YEAR(F25),MONTH(F25),1),$F:$F,$G:$G,"",1)-1 -> 0.0040788499 | K25: =_xlfn.STDEV.S(H6:H25)*SQRT(252) -> 0.19452752 | L25: =IF(G25>L24,G25,L24) -> 3433.65 | M25: =G25/L25-1 -> -0.0049073144 | R25: =Clean_Data!G24 -> 46119 | S25: =Clean_Data!I24 -> 8632.3 | T25: =S25/S24-1 -> -0.0023230549 | U25: =S25/S20-1 -> 0.047490999 | V25: =S25/_xlfn.XLOOKUP(DATE(YEAR(R25),MONTH(R25),1),$R:$R,$S:$S,"",1)-1 -> 0.0060088058 | W25: =_xlfn.STDEV.S(T6:T25)*SQRT(252) -> 0.20985759 | X25: =IF(S25>X24,S25,X24) -> 8652.4 | Y25: =S25/X25-1 -> -0.0023230549 | AE25: =Clean_Data!G24 -> 46119 | AF25: =Clean_Data!J24 -> 29749.2 | AG25: =AF25/AF24-1 -> -0.0044214914 | AH25: =AF25/AF20-1 -> 0.023859845 | AI25: =AF25/_xlfn.XLOOKUP(DATE(YEAR(AE25),MONTH(AE25),1),$AE:$AE,$AF:$AF,"",1)-1 -> -0.0053418757 | AJ25: =_xlfn.STDEV.S(AG6:AG25)*SQRT(252) -> 0.14829018 | AK25: =IF(AF25>AK24,AF25,AK24) -> 30686.76 | AL25: =AF25/AK25-1 -> -0.03055259 | AQ25: =Clean_Data!G24 -> 46119 | AR25: =Clean_Data!K24 -> 3.6888 | AS25: =AR25/AR24-1 -> -0.0082537976 | AT25: =AR25/AR20-1 -> -0.0085470085 | AU25: =AR25/_xlfn.XLOOKUP(DATE(YEAR(AQ25),MONTH(AE25),1),$AQ:$AQ,$AR:$AR,"",1)-1 -> -0.0022719896 | AV25: =_xlfn.STDEV.S(AS6:AS25)*SQRT(252) -> 0.12241326 | AW25: =IF(AR25>AW24,AR25,AW24) -> 3.7408 | AX25: =AR25/AW25-1 -> -0.01390077 | BC25: =Clean_Data!G24 -> 46119 | BD25: =Clean_Data!L24 -> 4.2694 | BE25: =BD25/BD24-1 -> -0.0040822039 | BF25: =BD25/BD20-1 -> -0.0038265901 | BG25: =BD25/_xlfn.XLOOKUP(DATE(YEAR(BC25),MONTH(AE25),1),$BC:$BC,$BD:$BD,"",1)-1 -> -0.0041983486 | BH25: =_xlfn.STDEV.S(BE6:BE25)*SQRT(252) -> 0.042822771 | BI25: =IF(BD25>BI24,BD25,BI24) -> 4.2894 | BJ25: =BD25/BI25-1 -> -0.0046626568 | BO25: =Clean_Data!G24 -> 46119 | BP25: =Clean_Data!M24 -> 557.13 | BQ25: =BP25/BP24-1 -> -0.0086125594 | BR25: =BP25/BP20-1 -> 0.060392082 | BS25: =BP25/_xlfn.XLOOKUP(DATE(YEAR(BO25),MONTH(AE25),1),$BO:$BO,$BP:$BP,"",1)-1 -> 0.014180653 | BT25: =_xlfn.STDEV.S(BQ6:BQ25)*SQRT(252) -> 0.42420221 | BU25: =IF(BP25>BU24,BP25,BU24) -> 615.05 | BV25: =BP25/BU25-1 -> -0.094171206
F26: =Clean_Data!G25 -> 46120 | G26: =Clean_Data!H25 -> 3533.95 | H26: =G26/G25-1 -> 0.034286467 | I26: =G26/G21-1 -> 0.07641956 | J26: =G26/_xlfn.XLOOKUP(DATE(YEAR(F26),MONTH(F26),1),$F:$F,$G:$G,"",1)-1 -> 0.038505166 | K26: =_xlfn.STDEV.S(H7:H26)*SQRT(252) -> 0.22418262 | L26: =IF(G26>L25,G26,L25) -> 3533.95 | M26: =G26/L26-1 -> 0 | R26: =Clean_Data!G25 -> 46120 | S26: =Clean_Data!I25 -> 8918.69 | T26: =S26/S25-1 -> 0.033176558 | U26: =S26/S21-1 -> 0.075982521 | V26: =S26/_xlfn.XLOOKUP(DATE(YEAR(R26),MONTH(R26),1),$R:$R,$S:$S,"",1)-1 -> 0.039384715 | W26: =_xlfn.STDEV.S(T7:T26)*SQRT(252) -> 0.23789162 | X26: =IF(S26>X25,S26,X25) -> 8918.69 | Y26: =S26/X26-1 -> 0 | AE26: =Clean_Data!G25 -> 46120 | AF26: =Clean_Data!J25 -> 30193.93 | AG26: =AF26/AF25-1 -> 0.01494931 | AH26: =AF26/AF21-1 -> 0.040538142 | AI26: =AF26/_xlfn.XLOOKUP(DATE(YEAR(AE26),MONTH(AE26),1),$AE:$AE,$AF:$AF,"",1)-1 -> 0.0095275765 | AJ26: =_xlfn.STDEV.S(AG7:AG26)*SQRT(252) -> 0.15635049 | AK26: =IF(AF26>AK25,AF26,AK25) -> 30686.76 | AL26: =AF26/AK26-1 -> -0.016060021 | AQ26: =Clean_Data!G25 -> 46120 | AR26: =Clean_Data!K25 -> 3.6489 | AS26: =AR26/AR25-1 -> -0.010816526 | AT26: =AR26/AR21-1 -> -0.020613576 | AU26: =AR26/_xlfn.XLOOKUP(DATE(YEAR(AQ26),MONTH(AE26),1),$AQ:$AQ,$AR:$AR,"",1)-1 -> -0.01306394 | AV26: =_xlfn.STDEV.S(AS7:AS26)*SQRT(252) -> 0.12750958 | AW26: =IF(AR26>AW25,AR26,AW25) -> 3.7408 | AX26: =AR26/AW26-1 -> -0.024566938 | BC26: =Clean_Data!G25 -> 46120 | BD26: =Clean_Data!L25 -> 4.2623 | BE26: =BD26/BD25-1 -> -0.0016629971 | BF26: =BD26/BD21-1 -> -0.0048795293 | BG26: =BD26/_xlfn.XLOOKUP(DATE(YEAR(BC26),MONTH(AE26),1),$BC:$BC,$BD:$BD,"",1)-1 -> -0.005854364 | BH26: =_xlfn.STDEV.S(BE7:BE26)*SQRT(252) -> 0.042847927 | BI26: =IF(BD26>BI25,BD26,BI25) -> 4.2894 | BJ26: =BD26/BI26-1 -> -0.0063178999 | BO26: =Clean_Data!G25 -> 46120 | BP26: =Clean_Data!M25 -> 555.24 | BQ26: =BP26/BP25-1 -> -0.003392386 | BR26: =BP26/BP21-1 -> 0.048295133 | BS26: =BP26/_xlfn.XLOOKUP(DATE(YEAR(BO26),MONTH(AE26),1),$BO:$BO,$BP:$BP,"",1)-1 -> 0.010740161 | BT26: =_xlfn.STDEV.S(BQ7:BQ26)*SQRT(252) -> 0.42375443 | BU26: =IF(BP26>BU25,BP26,BU25) -> 615.05 | BV26: =BP26/BU26-1 -> -0.097244126
F27: =Clean_Data!G26 -> 46121 | G27: =Clean_Data!H26 -> 3552.48 | H27: =G27/G26-1 -> 0.0052434245 | I27: =G27/G22-1 -> 0.063371618 | J27: =G27/_xlfn.XLOOKUP(DATE(YEAR(F27),MONTH(F27),1),$F:$F,$G:$G,"",1)-1 -> 0.04395049 | K27: =_xlfn.STDEV.S(H8:H27)*SQRT(252) -> 0.21460054 | L27: =IF(G27>L26,G27,L26) -> 3552.48 | M27: =G27/L27-1 -> 0 | R27: =Clean_Data!G26 -> 46121 | S27: =Clean_Data!I26 -> 8895.59 | T27: =S27/S26-1 -> -0.0025900665 | U27: =S27/S22-1 -> 0.050566761 | V27: =S27/_xlfn.XLOOKUP(DATE(YEAR(R27),MONTH(R27),1),$R:$R,$S:$S,"",1)-1 -> 0.03669264 | W27: =_xlfn.STDEV.S(T8:T27)*SQRT(252) -> 0.23576044 | X27: =IF(S27>X26,S27,X26) -> 8918.69 | Y27: =S27/X27-1 -> -0.0025900665 | AE27: =Clean_Data!G26 -> 46121 | AF27: =Clean_Data!J26 -> 30152.13 | AG27: =AF27/AF26-1 -> -0.0013843842 | AH27: =AF27/AF22-1 -> 0.018148782 | AI27: =AF27/_xlfn.XLOOKUP(DATE(YEAR(AE27),MONTH(AE27),1),$AE:$AE,$AF:$AF,"",1)-1 -> 0.0081300025 | AJ27: =_xlfn.STDEV.S(AG8:AG27)*SQRT(252) -> 0.15163746 | AK27: =IF(AF27>AK26,AF27,AK26) -> 30686.76 | AL27: =AF27/AK27-1 -> -0.017422172 | AQ27: =Clean_Data!G26 -> 46121 | AR27: =Clean_Data!K26 -> 3.6506 | AS27: =AR27/AR26-1 -> 0.00046589383 | AT27: =AR27/AR22-1 -> -0.024112489 | AU27: =AR27/_xlfn.XLOOKUP(DATE(YEAR(AQ27),MONTH(AE27),1),$AQ:$AQ,$AR:$AR,"",1)-1 -> -0.012604133 | AV27: =_xlfn.STDEV.S(AS8:AS27)*SQRT(252) -> 0.11609023 | AW27: =IF(AR27>AW26,AR27,AW26) -> 3.7408 | AX27: =AR27/AW27-1 -> -0.024112489 | BC27: =Clean_Data!G26 -> 46121 | BD27: =Clean_Data!L26 -> 4.261 | BE27: =BD27/BD26-1 -> -0.00030499965 | BF27: =BD27/BD22-1 -> -0.0066209726 | BG27: =BD27/_xlfn.XLOOKUP(DATE(YEAR(BC27),MONTH(AE27),1),$BC:$BC,$BD:$BD,"",1)-1 -> -0.006157578 | BH27: =_xlfn.STDEV.S(BE8:BE27)*SQRT(252) -> 0.035794739 | BI27: =IF(BD27>BI26,BD27,BI26) -> 4.2894 | BJ27: =BD27/BI27-1 -> -0.0066209726 | BO27: =Clean_Data!G26 -> 46121 | BP27: =Clean_Data!M26 -> 562.26 | BQ27: =BP27/BP26-1 -> 0.012643181 | BR27: =BP27/BP22-1 -> 0.034497985 | BS27: =BP27/_xlfn.XLOOKUP(DATE(YEAR(BO27),MONTH(AE27),1),$BO:$BO,$BP:$BP,"",1)-1 -> 0.023519132 | BT27: =_xlfn.STDEV.S(BQ8:BQ27)*SQRT(252) -> 0.42616306 | BU27: =IF(BP27>BU26,BP27,BU26) -> 615.05 | BV27: =BP27/BU27-1 -> -0.08583042
F28: =Clean_Data!G27 -> 46122 | G28: =Clean_Data!H27 -> 3596.84 | H28: =G28/G27-1 -> 0.012487051 | I28: =G28/G23-1 -> 0.056986353 | J28: =G28/_xlfn.XLOOKUP(DATE(YEAR(F28),MONTH(F28),1),$F:$F,$G:$G,"",1)-1 -> 0.056986353 | K28: =_xlfn.STDEV.S(H9:H28)*SQRT(252) -> 0.21487806 | L28: =IF(G28>L27,G28,L27) -> 3596.84 | M28: =G28/L28-1 -> 0 | R28: =Clean_Data!G27 -> 46122 | S28: =Clean_Data!I27 -> 9036.06 | T28: =S28/S27-1 -> 0.015790971 | U28: =S28/S23-1 -> 0.053063023 | V28: =S28/_xlfn.XLOOKUP(DATE(YEAR(R28),MONTH(R28),1),$R:$R,$S:$S,"",1)-1 -> 0.053063023 | W28: =_xlfn.STDEV.S(T9:T28)*SQRT(252) -> 0.23425767 | X28: =IF(S28>X27,S28,X27) -> 9036.06 | Y28: =S28/X28-1 -> 0 | AE28: =Clean_Data!G27 -> 46122 | AF28: =Clean_Data!J27 -> 30228.51 | AG28: =AF28/AF27-1 -> 0.0025331544 | AH28: =AF28/AF23-1 -> 0.010683751 | AI28: =AF28/_xlfn.XLOOKUP(DATE(YEAR(AE28),MONTH(AE28),1),$AE:$AE,$AF:$AF,"",1)-1 -> 0.010683751 | AJ28: =_xlfn.STDEV.S(AG9:AG28)*SQRT(252) -> 0.15192744 | AK28: =IF(AF28>AK27,AF28,AK27) -> 30686.76 | AL28: =AF28/AK28-1 -> -0.01493315 | AQ28: =Clean_Data!G27 -> 46122 | AR28: =Clean_Data!K27 -> 3.6396 | AS28: =AR28/AR27-1 -> -0.0030132033 | AT28: =AR28/AR23-1 -> -0.015579357 | AU28: =AR28/_xlfn.XLOOKUP(DATE(YEAR(AQ28),MONTH(AE28),1),$AQ:$AQ,$AR:$AR,"",1)-1 -> -0.015579357 | AV28: =_xlfn.STDEV.S(AS9:AS28)*SQRT(252) -> 0.11089187 | AW28: =IF(AR28>AW27,AR28,AW27) -> 3.7408 | AX28: =AR28/AW28-1 -> -0.027053037 | BC28: =Clean_Data!G27 -> 46122 | BD28: =Clean_Data!L27 -> 4.2534 | BE28: =BD28/BD27-1 -> -0.0017836189 | BF28: =BD28/BD23-1 -> -0.0079302141 | BG28: =BD28/_xlfn.XLOOKUP(DATE(YEAR(BC28),MONTH(AE28),1),$BC:$BC,$BD:$BD,"",1)-1 -> -0.0079302141 | BH28: =_xlfn.STDEV.S(BE9:BE28)*SQRT(252) -> 0.032538648 | BI28: =IF(BD28>BI27,BD28,BI27) -> 4.2894 | BJ28: =BD28/BI28-1 -> -0.0083927822 | BO28: =Clean_Data!G27 -> 46122 | BP28: =Clean_Data!M27 -> 554.6 | BQ28: =BP28/BP27-1 -> -0.013623591 | BR28: =BP28/BP23-1 -> 0.0095751265 | BS28: =BP28/_xlfn.XLOOKUP(DATE(YEAR(BO28),MONTH(AE28),1),$BO:$BO,$BP:$BP,"",1)-1 -> 0.0095751265 | BT28: =_xlfn.STDEV.S(BQ9:BQ28)*SQRT(252) -> 0.42737781 | BU28: =IF(BP28>BU27,BP28,BU27) -> 615.05 | BV28: =BP28/BU28-1 -> -0.098284692
F29: =Clean_Data!G28 -> 46125 | G29: =Clean_Data!H28 -> 3596.03 | H29: =G29/G28-1 -> -0.00022519767 | I29: =G29/G24-1 -> 0.047290784 | J29: =G29/_xlfn.XLOOKUP(DATE(YEAR(F29),MONTH(F29),1),$F:$F,$G:$G,"",1)-1 -> 0.056748322 | K29: =_xlfn.STDEV.S(H10:H29)*SQRT(252) -> 0.21188278 | L29: =IF(G29>L28,G29,L28) -> 3596.84 | M29: =G29/L29-1 -> -0.00022519767 | R29: =Clean_Data!G28 -> 46125 | S29: =Clean_Data!I28 -> 9031.26 | T29: =S29/S28-1 -> -0.00053120497 | U29: =S29/S24-1 -> 0.043786695 | V29: =S29/_xlfn.XLOOKUP(DATE(YEAR(R29),MONTH(R29),1),$R:$R,$S:$S,"",1)-1 -> 0.05250363 | W29: =_xlfn.STDEV.S(T10:T29)*SQRT(252) -> 0.22630879 | X29: =IF(S29>X28,S29,X28) -> 9036.06 | Y29: =S29/X29-1 -> -0.00053120497 | AE29: =Clean_Data!G28 -> 46125 | AF29: =Clean_Data!J28 -> 30393.35 | AG29: =AF29/AF28-1 -> 0.0054531302 | AH29: =AF29/AF24-1 -> 0.017135455 | AI29: =AF29/_xlfn.XLOOKUP(DATE(YEAR(AE29),MONTH(AE29),1),$AE:$AE,$AF:$AF,"",1)-1 -> 0.016195141 | AJ29: =_xlfn.STDEV.S(AG10:AG29)*SQRT(252) -> 0.15046366 | AK29: =IF(AF29>AK28,AF29,AK28) -> 30686.76 | AL29: =AF29/AK29-1 -> -0.0095614526 | AQ29: =Clean_Data!G28 -> 46125 | AR29: =Clean_Data!K28 -> 3.6374 | AS29: =AR29/AR28-1 -> -0.00060446203 | AT29: =AR29/AR24-1 -> -0.022072859 | AU29: =AR29/_xlfn.XLOOKUP(DATE(YEAR(AQ29),MONTH(AE29),1),$AQ:$AQ,$AR:$AR,"",1)-1 -> -0.016174402 | AV29: =_xlfn.STDEV.S(AS10:AS29)*SQRT(252) -> 0.11084762 | AW29: =IF(AR29>AW28,AR29,AW28) -> 3.7408 | AX29: =AR29/AW29-1 -> -0.027641146 | BC29: =Clean_Data!G28 -> 46125 | BD29: =Clean_Data!L28 -> 4.2507 | BE29: =BD29/BD28-1 -> -0.00063478629 | BF29: =BD29/BD24-1 -> -0.0084443304 | BG29: =BD29/_xlfn.XLOOKUP(DATE(YEAR(BC29),MONTH(AE29),1),$BC:$BC,$BD:$BD,"",1)-1 -> -0.0085599664 | BH29: =_xlfn.STDEV.S(BE10:BE29)*SQRT(252) -> 0.031377776 | BI29: =IF(BD29>BI28,BD29,BI28) -> 4.2894 | BJ29: =BD29/BI29-1 -> -0.0090222409 | BO29: =Clean_Data!G28 -> 46125 | BP29: =Clean_Data!M28 -> 554.64 | BQ29: =BP29/BP28-1 -> 7.2124053e-05 | BR29: =BP29/BP24-1 -> -0.013043401 | BS29: =BP29/_xlfn.XLOOKUP(DATE(YEAR(BO29),MONTH(AE29),1),$BO:$BO,$BP:$BP,"",1)-1 -> 0.0096479412 | BT29: =_xlfn.STDEV.S(BQ10:BQ29)*SQRT(252) -> 0.42420383 | BU29: =IF(BP29>BU28,BP29,BU28) -> 615.05 | BV29: =BP29/BU29-1 -> -0.098219657
F30: =Clean_Data!G29 -> 46126 | G30: =Clean_Data!H29 -> 3636.72 | H30: =G30/G29-1 -> 0.011315256 | I30: =G30/G25-1 -> 0.064364317 | J30: =G30/_xlfn.XLOOKUP(DATE(YEAR(F30),MONTH(F30),1),$F:$F,$G:$G,"",1)-1 -> 0.0687057 | K30: =_xlfn.STDEV.S(H11:H30)*SQRT(252) -> 0.21001088 | L30: =IF(G30>L29,G30,L29) -> 3636.72 | M30: =G30/L30-1 -> 0 | R30: =Clean_Data!G29 -> 46126 | S30: =Clean_Data!I29 -> 9144.9 | T30: =S30/S29-1 -> 0.012582962 | U30: =S30/S25-1 -> 0.059381625 | V30: =S30/_xlfn.XLOOKUP(DATE(YEAR(R30),MONTH(R30),1),$R:$R,$S:$S,"",1)-1 -> 0.065747243 | W30: =_xlfn.STDEV.S(T11:T30)*SQRT(252) -> 0.22788967 | X30: =IF(S30>X29,S30,X29) -> 9144.9 | Y30: =S30/X30-1 -> 0 | AE30: =Clean_Data!G29 -> 46126 | AF30: =Clean_Data!J29 -> 30612.86 | AG30: =AF30/AF29-1 -> 0.0072223036 | AH30: =AF30/AF25-1 -> 0.029031369 | AI30: =AF30/_xlfn.XLOOKUP(DATE(YEAR(AE30),MONTH(AE30),1),$AE:$AE,$AF:$AF,"",1)-1 -> 0.023534411 | AJ30: =_xlfn.STDEV.S(AG11:AG30)*SQRT(252) -> 0.15175744 | AK30: =IF(AF30>AK29,AF30,AK29) -> 30686.76 | AL30: =AF30/AK30-1 -> -0.0024082047 | AQ30: =Clean_Data!G29 -> 46126 | AR30: =Clean_Data!K29 -> 3.6015 | AS30: =AR30/AR29-1 -> -0.0098696871 | AT30: =AR30/AR25-1 -> -0.023666233 | AU30: =AR30/_xlfn.XLOOKUP(DATE(YEAR(AQ30),MONTH(AE30),1),$AQ:$AQ,$AR:$AR,"",1)-1 -> -0.025884453 | AV30: =_xlfn.STDEV.S(AS11:AS30)*SQRT(252) -> 0.10666755 | AW30: =IF(AR30>AW29,AR30,AW29) -> 3.7408 | AX30: =AR30/AW30-1 -> -0.037238024 | BC30: =Clean_Data!G29 -> 46126 | BD30: =Clean_Data!L29 -> 4.2436 | BE30: =BD30/BD29-1 -> -0.0016703131 | BF30: =BD30/BD25-1 -> -0.0060430037 | BG30: =BD30/_xlfn.XLOOKUP(DATE(YEAR(BC30),MONTH(AE30),1),$BC:$BC,$BD:$BD,"",1)-1 -> -0.010215982 | BH30: =_xlfn.STDEV.S(BE11:BE30)*SQRT(252) -> 0.031194605 | BI30: =IF(BD30>BI29,BD30,BI29) -> 4.2894 | BJ30: =BD30/BI30-1 -> -0.010677484 | BO30: =Clean_Data!G29 -> 46126 | BP30: =Clean_Data!M29 -> 552.27 | BQ30: =BP30/BP29-1 -> -0.004273042 | BR30: =BP30/BP25-1 -> -0.0087232782 | BS30: =BP30/_xlfn.XLOOKUP(DATE(YEAR(BO30),MONTH(AE30),1),$BO:$BO,$BP:$BP,"",1)-1 -> 0.0053336731 | BT30: =_xlfn.STDEV.S(BQ11:BQ30)*SQRT(252) -> 0.42377947 | BU30: =IF(BP30>BU29,BP30,BU29) -> 615.05 | BV30: =BP30/BU30-1 -> -0.102073
